Workbook
Name Age: '[1]Calc Engine'!$C$31:$C$89
Name Age: '[2]Calc Engine'!$C$31:$C$89
Name Age: '[2]Calc Engine'!$C$31:$C$89
Name Age: 'Calc Engine'!$C$31:$C$89
Name Allocation_Large_Cap: 'Calc Engine'!$AM$21
Name Allocation_Mid_Cap: 'Calc Engine'!$AM$22
Name Allocation_Small_Cap: 'Calc Engine'!$AM$23
Name End_Of_Year_Value_Large_Cap: '[1]Calc Engine'!$AO$31:$AO$89
Name End_Of_Year_Value_Large_Cap: '[2]Calc Engine'!$AO$31:$AO$89
Name End_Of_Year_Value_Large_Cap: '[2]Calc Engine'!$AO$31:$AO$89
Name End_Of_Year_Value_Large_Cap: 'Calc Engine'!$AO$31:$AO$89
Name End_Of_Year_Value_Mid_Cap: '[1]Calc Engine'!$AT$31:$AT$89
Name End_Of_Year_Value_Mid_Cap: '[2]Calc Engine'!$AT$31:$AT$89
Name End_Of_Year_Value_Mid_Cap: '[2]Calc Engine'!$AT$31:$AT$89
Name End_Of_Year_Value_Mid_Cap: 'Calc Engine'!$AT$31:$AT$89
Name End_Of_Year_Value_Small_Cap: '[1]Calc Engine'!$AY$31:$AY$89
Name End_Of_Year_Value_Small_Cap: '[2]Calc Engine'!$AY$31:$AY$89
Name End_Of_Year_Value_Small_Cap: '[2]Calc Engine'!$AY$31:$AY$89
Name End_Of_Year_Value_Small_Cap: 'Calc Engine'!$AY$31:$AY$89
Name Opening_Savings: Details!$V$20
Name Opening_Savings: [2]Details!$V$20
Name Opening_Savings: [1]Details!$V$20
Name Total_Surplus: '[1]Calc Engine'!$BH$5
Name Total_Surplus: '[2]Calc Engine'!$BH$5
Name Total_Surplus: '[2]Calc Engine'!$BH$5
Name Total_Surplus: 'Calc Engine'!$BH$5

Sheet Details
B2: Name | C2: Gaurav Agarwal
B3: Start Age | C3: 20
B4: Goal Age | C4: 55
S6: Portfolio Structure
B7: Income | F7: Expenses | J7: Goal | U7: 1 | V7: 2 | W7: 3 | X7: 4 | Y7: 5 | Z7: 6 | AB7: Scenario Structure
B8: Annual | C8: =SUM(Details!$C$14:$C$18) -> 726000 | D8: =SUM(Details!$D$14:$D$18) -> 1 | F8: Annual | G8: =SUM(Details!$G$14:$G$22) -> 210000 | H8: =IFERROR($G8/$C$8,"-") -> 0.2892562 | U8: Share (%) | V8: Share (%) | W8: Share (%) | X8: Share (%) | Y8: Share (%) | Z8: Share (%) | AC8: Best | AD8: Medium | AE8: Worst
F9: Balance | G9: =(C8-G8) -> 516000 | H9: =1-H8 -> 0.7107438 | K9: 1 - least imp | S9: Large Cap | U9: 0.2 | V9: 0 | W9: 0.2 | X9: 0.9 | Y9: 0.1 | Z9: 0.8 | AB9: Good | AC9: 0.8 | AD9: 0.2 | AE9: 0
F10: Minimum amount to invest | G10: 40000 | H10: =IF(G10>G9,"Insufficent","-") -> - | K10: 3 - most imp | S10: Mid Cap | U10: 0.5 | V10: 0.5 | W10: 0.7 | X10: 0.05 | Y10: 0.05 | Z10: 0.1 | AB10: Mid | AC10: 0.1 | AD10: 0.5 | AE10: 0.2
F11: Yearly Increment in Investment Amount | H11: 0.1 | L11: In Rs - Goal Value | S11: Small Cap | U11: 0.3 | V11: 0.5 | W11: 0.1 | X11: 0.05 | Y11: 0.9 | Z11: 0.1 | AB11: Worst | AC11: 0.1 | AD11: 0.3 | AE11: 0.8
L12: Source | S12: % of Goals Met | U12: ='[2]Calc Engine'!$BF3 -> #REF! | V12: =#REF! -> #REF! | W12: =#REF! -> #REF! | X12: =#REF! -> #REF! | Y12: =#REF! -> #REF! | Z12: =#REF! -> #REF! | AC12: =IF(SUM(AC9:AC11) = 1, "", "Sum != 1") | AD12: =IF(SUM(AD9:AD11) = 1, "", "Sum != 1") | AE12: =IF(SUM(AE9:AE11) = 1, "", "Sum != 1")
B13: Category | C13: in Rs | D13: in % | F13: Category | G13: in Rs | H13: in % | J13: Goal | K13: Goal Importance | L13: At Age | M13: Large Cap | N13: Mid Cap | O13: Small Cap | AB13: Select The Sceanario | AE13: Best
B14: Salary | C14: 720000 | D14: =IFERROR($C14/$C$8,"-") -> 0.99173554 | F14: EMI | G14: 0 | H14: =IFERROR($G14/$C$8,"-") -> 0 | J14: Own Health Fund | K14: 1 | L14: 32 | M14: 660000 | N14: 0 | P14: =IF(NOT(ISBLANK(Goal_Input[[#This Row],[Goal]])),IF([2]Details!$M14>0,IF(_xlfn.XLOOKUP([2]Details!$L14,'[2]Calc Engine'!$C$31:$C$66,'[2]Calc Engine'!$AO$31:$AO$66)>[2]Details!$M14,"Goal Met","Goal Not Met"),"Goal Met"),"-") -> Goal Not Met | Q14: =IF(NOT(ISBLANK(Goal_Input[[#This Row],[Goal]])),IF([2]Details!$N14>0,IF(_xlfn.XLOOKUP([2]Details!$L14,'[2]Calc Engine'!$C$31:$C$66,'[2]Calc Engine'!$AT$31:$AT$66)>[2]Details!$N14,"Goal Met","Goal Not Met"),"Goal Met"),"-") -> Goal Met | R14: =IF(NOT(ISBLANK(Goal_Input[[#This Row],[Goal]])),IF([2]Details!$O14>0,IF(_xlfn.XLOOKUP([2]Details!$L14,'[2]Calc Engine'!$C$31:$C$66,'[2]Calc Engine'!$AY$31:$AY$66)>[2]Details!$O14,"Goal Met","Goal Not Met"),"Goal Met"),"-") -> Goal Met | S14: =IF(AND(P14="Goal Met",Q14="Goal Met",R14="Goal Met"),"Goal Met",IF(ISBLANK(Goal_Input[[#This Row],[Goal]]),"-","Change Allocation")) -> Change Allocation
B15: Rent | C15: 0 | D15: =IFERROR($C15/$C$8,"-") -> 0 | F15: Entertainment | G15: 18000 | H15: =IFERROR($G15/$C$8,"-") -> 0.024793388 | J15: Marriage | K15: 1 | L15: 35 | M15: 0 | N15: 340000 | O15: 0 | P15: =IF(NOT(ISBLANK(Goal_Input[[#This Row],[Goal]])),IF([2]Details!$M15>0,IF(_xlfn.XLOOKUP([2]Details!$L15,'[2]Calc Engine'!$C$31:$C$66,'[2]Calc Engine'!$AO$31:$AO$66)>[2]Details!$M15,"Goal Met","Goal Not Met"),"Goal Met"),"-") -> Goal Met | Q15: =IF(NOT(ISBLANK(Goal_Input[[#This Row],[Goal]])),IF([2]Details!$N15>0,IF(_xlfn.XLOOKUP([2]Details!$L15,'[2]Calc Engine'!$C$31:$C$66,'[2]Calc Engine'!$AT$31:$AT$66)>[2]Details!$N15,"Goal Met","Goal Not Met"),"Goal Met"),"-") -> Goal Not Met | R15: =IF(NOT(ISBLANK(Goal_Input[[#This Row],[Goal]])),IF([2]Details!$O15>0,IF(_xlfn.XLOOKUP([2]Details!$L15,'[2]Calc Engine'!$C$31:$C$66,'[2]Calc Engine'!$AY$31:$AY$66)>[2]Details!$O15,"Goal Met","Goal Not Met"),"Goal Met"),"-") -> Goal Met | S15: =IF(AND(P15="Goal Met",Q15="Goal Met",R15="Goal Met"),"Goal Met",IF(ISBLANK(Goal_Input[[#This Row],[Goal]]),"-","Change Allocation")) -> Change Allocation
B16: Interest | C16: 6000 | D16: =IFERROR($C16/$C$8,"-") -> 0.0082644628 | F16: Food | G16: 36000 | H16: =IFERROR($G16/$C$8,"-") -> 0.049586777 | J16: Children Education | K16: 1 | L16: 42 | M16: 430000 | N16: 0 | P16: =IF(NOT(ISBLANK(Goal_Input[[#This Row],[Goal]])),IF([2]Details!$M16>0,IF(_xlfn.XLOOKUP([2]Details!$L16,'[2]Calc Engine'!$C$31:$C$66,'[2]Calc Engine'!$AO$31:$AO$66)>[2]Details!$M16,"Goal Met","Goal Not Met"),"Goal Met"),"-") -> Goal Not Met | Q16: =IF(NOT(ISBLANK(Goal_Input[[#This Row],[Goal]])),IF([2]Details!$N16>0,IF(_xlfn.XLOOKUP([2]Details!$L16,'[2]Calc Engine'!$C$31:$C$66,'[2]Calc Engine'!$AT$31:$AT$66)>[2]Details!$N16,"Goal Met","Goal Not Met"),"Goal Met"),"-") -> Goal Met | R16: =IF(NOT(ISBLANK(Goal_Input[[#This Row],[Goal]])),IF([2]Details!$O16>0,IF(_xlfn.XLOOKUP([2]Details!$L16,'[2]Calc Engine'!$C$31:$C$66,'[2]Calc Engine'!$AY$31:$AY$66)>[2]Details!$O16,"Goal Met","Goal Not Met"),"Goal Met"),"-") -> Goal Met | S16: =IF(AND(P16="Goal Met",Q16="Goal Met",R16="Goal Met"),"Goal Met",IF(ISBLANK(Goal_Input[[#This Row],[Goal]]),"-","Change Allocation")) -> Change Allocation | AB16: Chosen Scenario
B17: Business Income | C17: 0 | D17: =IFERROR($C17/$C$8,"-") -> 0 | F17: Recreation | G17: 12000 | H17: =IFERROR($G17/$C$8,"-") -> 0.016528926 | J17: House | K17: 1 | L17: 52 | M17: =6000000 -> 6000000 | N17: 0 | O17: 0 | P17: =IF(NOT(ISBLANK(Goal_Input[[#This Row],[Goal]])),IF([2]Details!$M17>0,IF(_xlfn.XLOOKUP([2]Details!$L17,'[2]Calc Engine'!$C$31:$C$66,'[2]Calc Engine'!$AO$31:$AO$66)>[2]Details!$M17,"Goal Met","Goal Not Met"),"Goal Met"),"-") -> Goal Not Met | Q17: =IF(NOT(ISBLANK(Goal_Input[[#This Row],[Goal]])),IF([2]Details!$N17>0,IF(_xlfn.XLOOKUP([2]Details!$L17,'[2]Calc Engine'!$C$31:$C$66,'[2]Calc Engine'!$AT$31:$AT$66)>[2]Details!$N17,"Goal Met","Goal Not Met"),"Goal Met"),"-") -> Goal Met | R17: =IF(NOT(ISBLANK(Goal_Input[[#This Row],[Goal]])),IF([2]Details!$O17>0,IF(_xlfn.XLOOKUP([2]Details!$L17,'[2]Calc Engine'!$C$31:$C$66,'[2]Calc Engine'!$AY$31:$AY$66)>[2]Details!$O17,"Goal Met","Goal Not Met"),"Goal Met"),"-") -> Goal Met | S17: =IF(AND(P17="Goal Met",Q17="Goal Met",R17="Goal Met"),"Goal Met",IF(ISBLANK(Goal_Input[[#This Row],[Goal]]),"-","Change Allocation")) -> Change Allocation | T17: Bank Structure | AB17: Good | AC17: =INDEX($AC$9:$AE$11,MATCH($AB17,$AB$9:$AB$11,0),MATCH($AE$13,$AC$8:$AE$8,0)) -> 0.8
B18: Other Income | C18: - | D18: =IFERROR($C18/$C$8,"-") -> - | F18: Medical expenses | G18: 6000 | H18: =IFERROR($G18/$C$8,"-") -> 0.0082644628 | J18: Car | K18: 1 | L18: 28 | M18: 0 | N18: 209000 | O18: 0 | P18: =IF(NOT(ISBLANK(Goal_Input[[#This Row],[Goal]])),IF([2]Details!$M18>0,IF(_xlfn.XLOOKUP([2]Details!$L18,'[2]Calc Engine'!$C$31:$C$66,'[2]Calc Engine'!$AO$31:$AO$66)>[2]Details!$M18,"Goal Met","Goal Not Met"),"Goal Met"),"-") -> Goal Met | Q18: =IF(NOT(ISBLANK(Goal_Input[[#This Row],[Goal]])),IF([2]Details!$N18>0,IF(_xlfn.XLOOKUP([2]Details!$L18,'[2]Calc Engine'!$C$31:$C$66,'[2]Calc Engine'!$AT$31:$AT$66)>[2]Details!$N18,"Goal Met","Goal Not Met"),"Goal Met"),"-") -> Goal Not Met | R18: =IF(NOT(ISBLANK(Goal_Input[[#This Row],[Goal]])),IF([2]Details!$O18>0,IF(_xlfn.XLOOKUP([2]Details!$L18,'[2]Calc Engine'!$C$31:$C$66,'[2]Calc Engine'!$AY$31:$AY$66)>[2]Details!$O18,"Goal Met","Goal Not Met"),"Goal Met"),"-") -> Goal Met | S18: =IF(AND(P18="Goal Met",Q18="Goal Met",R18="Goal Met"),"Goal Met",IF(ISBLANK(Goal_Input[[#This Row],[Goal]]),"-","Change Allocation")) -> Change Allocation | T18: Min Balance | V18: 100000 | AB18: Mid | AC18: =INDEX($AC$9:$AE$11,MATCH($AB18,$AB$9:$AB$11,0),MATCH($AE$13,$AC$8:$AE$8,0)) -> 0.1
F19: Luxury | G19: 24000 | H19: =IFERROR($G19/$C$8,"-") -> 0.033057851 | J19: Abroad Vacation | K19: 1 | L19: 38 | M19: 0 | N19: 0 | O19: 5500000 | P19: =IF(NOT(ISBLANK(Goal_Input[[#This Row],[Goal]])),IF([2]Details!$M19>0,IF(_xlfn.XLOOKUP([2]Details!$L19,'[2]Calc Engine'!$C$31:$C$66,'[2]Calc Engine'!$AO$31:$AO$66)>[2]Details!$M19,"Goal Met","Goal Not Met"),"Goal Met"),"-") -> Goal Met | Q19: =IF(NOT(ISBLANK(Goal_Input[[#This Row],[Goal]])),IF([2]Details!$N19>0,IF(_xlfn.XLOOKUP([2]Details!$L19,'[2]Calc Engine'!$C$31:$C$66,'[2]Calc Engine'!$AT$31:$AT$66)>[2]Details!$N19,"Goal Met","Goal Not Met"),"Goal Met"),"-") -> Goal Met | R19: =IF(NOT(ISBLANK(Goal_Input[[#This Row],[Goal]])),IF([2]Details!$O19>0,IF(_xlfn.XLOOKUP([2]Details!$L19,'[2]Calc Engine'!$C$31:$C$66,'[2]Calc Engine'!$AY$31:$AY$66)>[2]Details!$O19,"Goal Met","Goal Not Met"),"Goal Met"),"-") -> Goal Met | S19: =IF(AND(P19="Goal Met",Q19="Goal Met",R19="Goal Met"),"Goal Met",IF(ISBLANK(Goal_Input[[#This Row],[Goal]]),"-","Change Allocation")) -> Goal Met | T19: FD Amount | V19: 300000 | AB19: Worst | AC19: =INDEX($AC$9:$AE$11,MATCH($AB19,$AB$9:$AB$11,0),MATCH($AE$13,$AC$8:$AE$8,0)) -> 0.1
F20: Transportation | G20: 18000 | H20: =IFERROR($G20/$C$8,"-") -> 0.024793388 | K20: 1 | L20: 0 | M20: 0 | N20: 0 | O20: 0 | P20: =IF(NOT(ISBLANK(Goal_Input[[#This Row],[Goal]])),IF([2]Details!$M20>0,IF(_xlfn.XLOOKUP([2]Details!$L20,'[2]Calc Engine'!$C$31:$C$66,'[2]Calc Engine'!$AO$31:$AO$66)>[2]Details!$M20,"Goal Met","Goal Not Met"),"Goal Met"),"-") -> - | Q20: =IF(NOT(ISBLANK(Goal_Input[[#This Row],[Goal]])),IF([2]Details!$N20>0,IF(_xlfn.XLOOKUP([2]Details!$L20,'[2]Calc Engine'!$C$31:$C$66,'[2]Calc Engine'!$AT$31:$AT$66)>[2]Details!$N20,"Goal Met","Goal Not Met"),"Goal Met"),"-") -> - | R20: =IF(NOT(ISBLANK(Goal_Input[[#This Row],[Goal]])),IF([2]Details!$O20>0,IF(_xlfn.XLOOKUP([2]Details!$L20,'[2]Calc Engine'!$C$31:$C$66,'[2]Calc Engine'!$AY$31:$AY$66)>[2]Details!$O20,"Goal Met","Goal Not Met"),"Goal Met"),"-") -> - | S20: =IF(AND(P20="Goal Met",Q20="Goal Met",R20="Goal Met"),"Goal Met",IF(ISBLANK(Goal_Input[[#This Row],[Goal]]),"-","Change Allocation")) -> - | T20: Opening Bank Bal | V20: 80000
F21: Household Expenses | G21: 84000 | H21: =IFERROR($G21/$C$8,"-") -> 0.11570248 | K21: 1 | L21: 0 | M21: 0 | N21: 0 | O21: 0 | P21: =IF(NOT(ISBLANK(Goal_Input[[#This Row],[Goal]])),IF([2]Details!$M21>0,IF(_xlfn.XLOOKUP([2]Details!$L21,'[2]Calc Engine'!$C$31:$C$66,'[2]Calc Engine'!$AO$31:$AO$66)>[2]Details!$M21,"Goal Met","Goal Not Met"),"Goal Met"),"-") -> - | Q21: =IF(NOT(ISBLANK(Goal_Input[[#This Row],[Goal]])),IF([2]Details!$N21>0,IF(_xlfn.XLOOKUP([2]Details!$L21,'[2]Calc Engine'!$C$31:$C$66,'[2]Calc Engine'!$AT$31:$AT$66)>[2]Details!$N21,"Goal Met","Goal Not Met"),"Goal Met"),"-") -> - | R21: =IF(NOT(ISBLANK(Goal_Input[[#This Row],[Goal]])),IF([2]Details!$O21>0,IF(_xlfn.XLOOKUP([2]Details!$L21,'[2]Calc Engine'!$C$31:$C$66,'[2]Calc Engine'!$AY$31:$AY$66)>[2]Details!$O21,"Goal Met","Goal Not Met"),"Goal Met"),"-") -> - | S21: =IF(AND(P21="Goal Met",Q21="Goal Met",R21="Goal Met"),"Goal Met",IF(ISBLANK(Goal_Input[[#This Row],[Goal]]),"-","Change Allocation")) -> -
F22: Insurance | G22: 12000 | H22: =IFERROR($G22/$C$8,"-") -> 0.016528926 | K22: 1 | L22: 0 | M22: 0 | N22: 0 | O22: 0 | P22: =IF(NOT(ISBLANK(Goal_Input[[#This Row],[Goal]])),IF([2]Details!$M22>0,IF(_xlfn.XLOOKUP([2]Details!$L22,'[2]Calc Engine'!$C$31:$C$66,'[2]Calc Engine'!$AO$31:$AO$66)>[2]Details!$M22,"Goal Met","Goal Not Met"),"Goal Met"),"-") -> - | Q22: =IF(NOT(ISBLANK(Goal_Input[[#This Row],[Goal]])),IF([2]Details!$N22>0,IF(_xlfn.XLOOKUP([2]Details!$L22,'[2]Calc Engine'!$C$31:$C$66,'[2]Calc Engine'!$AT$31:$AT$66)>[2]Details!$N22,"Goal Met","Goal Not Met"),"Goal Met"),"-") -> - | R22: =IF(NOT(ISBLANK(Goal_Input[[#This Row],[Goal]])),IF([2]Details!$O22>0,IF(_xlfn.XLOOKUP([2]Details!$L22,'[2]Calc Engine'!$C$31:$C$66,'[2]Calc Engine'!$AY$31:$AY$66)>[2]Details!$O22,"Goal Met","Goal Not Met"),"Goal Met"),"-") -> - | S22: =IF(AND(P22="Goal Met",Q22="Goal Met",R22="Goal Met"),"Goal Met",IF(ISBLANK(Goal_Input[[#This Row],[Goal]]),"-","Change Allocation")) -> -
F23: Ad Hoc | G23: 24000 | H23: =IFERROR($G23/$C$8,"-") -> 0.033057851 | K23: 1 | L23: 0 | M23: 0 | N23: 0 | O23: 0 | P23: =IF(NOT(ISBLANK(Goal_Input[[#This Row],[Goal]])),IF([2]Details!$M23>0,IF(_xlfn.XLOOKUP([2]Details!$L23,'[2]Calc Engine'!$C$31:$C$66,'[2]Calc Engine'!$AO$31:$AO$66)>[2]Details!$M23,"Goal Met","Goal Not Met"),"Goal Met"),"-") -> - | Q23: =IF(NOT(ISBLANK(Goal_Input[[#This Row],[Goal]])),IF([2]Details!$N23>0,IF(_xlfn.XLOOKUP([2]Details!$L23,'[2]Calc Engine'!$C$31:$C$66,'[2]Calc Engine'!$AT$31:$AT$66)>[2]Details!$N23,"Goal Met","Goal Not Met"),"Goal Met"),"-") -> - | R23: =IF(NOT(ISBLANK(Goal_Input[[#This Row],[Goal]])),IF([2]Details!$O23>0,IF(_xlfn.XLOOKUP([2]Details!$L23,'[2]Calc Engine'!$C$31:$C$66,'[2]Calc Engine'!$AY$31:$AY$66)>[2]Details!$O23,"Goal Met","Goal Not Met"),"Goal Met"),"-") -> - | S23: =IF(AND(P23="Goal Met",Q23="Goal Met",R23="Goal Met"),"Goal Met",IF(ISBLANK(Goal_Input[[#This Row],[Goal]]),"-","Change Allocation")) -> -

Sheet Assumptions Sheet
R4: Expense Infaltion
E6: Case | F6: Probability | I6: Real Return
E7: Good | F7: =Details!AC17 -> 0.8 | H7: Growth > Inflation | I7: +
E8: Mid | F8: =Details!AC18 -> 0.1 | H8: Growth = Inflation | I8: 0
E9: Bad | F9: =Details!AC19 -> 0.1 | H9: Growth < Inflation | I9: -
E12: Growth | O12: Inflation | AA12: Investment Returns
C13: Probablities | E13: {=TRANSPOSE([1]Details!$B$14:$B$18)} -> Salary | F13: Rent | G13: Interest | H13: Business Income | I13: Other Income | O13: Inflation | P13: Food Inflation | Q13: Retail Inflation | R13: Energy Inflation | S13: Medical Inflation | T13: Household Inflation | V13: Ad Hoc Expenses | AA13: Large Cap | AB13: Mid Cap | AC13: Small Cap | AD13: FD | AE13: Savings Account
B14: {='Assumptions Sheet'!$E$7:$F$9} -> Good | C14: 0.8 | D14: =C14 -> 0.8 | E14: 0.1 | F14: 0.05 | G14: 0.05 | H14: 0.1 | I14: 0 | O14: 0.05 | P14: 0.04 | Q14: 0.08 | R14: 0.06 | S14: 0.04 | T14: =O14 -> 0.05 | V14: 10000 | X14: Probablity of Below Avg Performance | Y14: =C14 -> 0.8 | Z14: =Y14 -> 0.8 | AA14: 0.14 | AB14: 0.16 | AC14: 0.2 | AD14: 0.05 | AE14: 0.03
B15: Mid | C15: 0.1 | D15: =SUM(C14:C15) -> 0.9 | E15: 0.07 | F15: 0.05 | G15: 0.05 | H15: 0.05 | I15: 0 | O15: 0.06 | P15: 0.05 | Q15: 0.05 | R15: 0.06 | S15: 0.04 | T15: 0.04 | V15: 15000 | X15: Probablity of Avg Performance | Y15: =C15 -> 0.1 | Z15: =SUM(Y14:Y15) -> 0.9 | AA15: 0.12 | AB15: 0.14 | AC15: 0.16 | AD15: 0.05 | AE15: 0.03
B16: Bad | C16: 0.1 | D16: =SUM(C14:C16) -> 1 | E16: 0.04 | F16: 0.05 | G16: 0.05 | H16: 0.01 | I16: 0 | O16: 0.08 | P16: 0.07 | Q16: 0.1 | R16: 0.06 | S16: 0.04 | T16: 0.08 | V16: 30000 | X16: Porbablity of Above Avg | Y16: =C16 -> 0.1 | Z16: =SUM(Y14:Y16) -> 1 | AA16: 0.09 | AB16: 0.12 | AC16: 0.14 | AD16: 0.05 | AE16: 0.03
E20: =E13 -> Salary | F20: =F13 -> Rent | G20: =G13 -> Interest | H20: =H13 -> Business Income | I20: =I13 -> Other Income | O20: General Expense | P20: Food | Q20: Retail Purchases | R20: Transport | S20: Medical Expenses | T20: Household Expenses | U20: Insurance | AA20: =AA13 -> Large Cap | AB20: =AB13 -> Mid Cap | AC20: =AC13 -> Small Cap | AD20: =AD13 -> FD | AE20: =AE13 -> Savings Account
A21: {=_xlfn.SEQUENCE([1]Details!C4-[1]Details!C3,1,[1]Details!C3,1)} -> 20 | B21: 0.47881104 | C21: =RAND() -> 0.92532471 | E21: {=_xlfn.IFS($C21<$D$14,E$14, $C21<$D$15,E$15, $C21<$D$16,E$16)} -> 0.04 | F21: {=_xlfn.IFS($C21<$D$14,F$14, $C21<$D$15,F$15, $C21<$D$16,F$16)} -> 0.05 | G21: {=_xlfn.IFS($C21<$D$14,G$14, $C21<$D$15,G$15, $C21<$D$16,G$16)} -> 0.05 | H21: {=_xlfn.IFS($C21<$D$14,H$14, $C21<$D$15,H$15, $C21<$D$16,H$16)} -> 0.01 | I21: {=_xlfn.IFS($C21<$D$14,I$14, $C21<$D$15,I$15, $C21<$D$16,I$16)} -> 0 | O21: {=_xlfn.IFS($C21<$D$14,O$14, $C21<$D$15,O$15, $C21<$D$16,O$16)} -> 0.08 | P21: {=_xlfn.IFS($C21<$D$14,P$14, $C21<$D$15,P$15, $C21<$D$16,P$16)} -> 0.07 | Q21: {=_xlfn.IFS($C21<$D$14,Q$14, $C21<$D$15,Q$15, $C21<$D$16,Q$16)} -> 0.1 | R21: {=_xlfn.IFS($C21<$D$14,R$14, $C21<$D$15,R$15, $C21<$D$16,R$16)} -> 0.06 | S21: {=_xlfn.IFS($C21<$D$14,S$14, $C21<$D$15,S$15, $C21<$D$16,S$16)} -> 0.04 | T21: {=_xlfn.IFS($C21<$D$14,T$14, $C21<$D$15,T$15, $C21<$D$16,T$16)} -> 0.08 | U21: {=_xlfn.IFS($C21<$D$14,U$14, $C21<$D$15,U$15, $C21<$D$16,U$16)} -> 0 | V21: {=_xlfn.IFS($C21<$D$14,V$14, $C21<$D$15,V$15, $C21<$D$16,V$16)} -> 30000 | AA21: {=_xlfn.IFS($C21<$Z$14,AA$14, $C21<$Z$15,AA$15, $C21<$Z$16,AA$16)} -> 0.09 | AB21: {=_xlfn.IFS($C21<$Z$14,AB$14, $C21<$Z$15,AB$15, $C21<$Z$16,AB$16)} -> 0.12 | AC21: {=_xlfn.IFS($C21<$Z$14,AC$14, $C21<$Z$15,AC$15, $C21<$Z$16,AC$16)} -> 0.14 | AD21: {=_xlfn.IFS($C21<$Z$14,AD$14, $C21<$Z$15,AD$15, $C21<$Z$16,AD$16)} -> 0.05 | AE21: {=_xlfn.IFS($C21<$Z$14,AE$14, $C21<$Z$15,AE$15, $C21<$Z$16,AE$16)} -> 0.03
A22: 21 | B22: 0.024462289 | C22: =RAND() -> 0.76031527 | E22: {=_xlfn.IFS($C22<$D$14,E$14, $C22<$D$15,E$15, $C22<$D$16,E$16)} -> 0.1 | F22: {=_xlfn.IFS($C22<$D$14,F$14, $C22<$D$15,F$15, $C22<$D$16,F$16)} -> 0.05 | G22: {=_xlfn.IFS($C22<$D$14,G$14, $C22<$D$15,G$15, $C22<$D$16,G$16)} -> 0.05 | H22: {=_xlfn.IFS($C22<$D$14,H$14, $C22<$D$15,H$15, $C22<$D$16,H$16)} -> 0.1 | I22: {=_xlfn.IFS($C22<$D$14,I$14, $C22<$D$15,I$15, $C22<$D$16,I$16)} -> 0 | O22: {=_xlfn.IFS($C22<$D$14,O$14, $C22<$D$15,O$15, $C22<$D$16,O$16)} -> 0.05 | P22: {=_xlfn.IFS($C22<$D$14,P$14, $C22<$D$15,P$15, $C22<$D$16,P$16)} -> 0.04 | Q22: {=_xlfn.IFS($C22<$D$14,Q$14, $C22<$D$15,Q$15, $C22<$D$16,Q$16)} -> 0.08 | R22: {=_xlfn.IFS($C22<$D$14,R$14, $C22<$D$15,R$15, $C22<$D$16,R$16)} -> 0.06 | S22: {=_xlfn.IFS($C22<$D$14,S$14, $C22<$D$15,S$15, $C22<$D$16,S$16)} -> 0.04 | T22: {=_xlfn.IFS($C22<$D$14,T$14, $C22<$D$15,T$15, $C22<$D$16,T$16)} -> 0.05 | U22: {=_xlfn.IFS($C22<$D$14,U$14, $C22<$D$15,U$15, $C22<$D$16,U$16)} -> 0 | V22: {=_xlfn.IFS($C22<$D$14,V$14, $C22<$D$15,V$15, $C22<$D$16,V$16)} -> 10000 | AA22: {=_xlfn.IFS($C22<$Z$14,AA$14, $C22<$Z$15,AA$15, $C22<$Z$16,AA$16)} -> 0.14 | AB22: {=_xlfn.IFS($C22<$Z$14,AB$14, $C22<$Z$15,AB$15, $C22<$Z$16,AB$16)} -> 0.16 | AC22: {=_xlfn.IFS($C22<$Z$14,AC$14, $C22<$Z$15,AC$15, $C22<$Z$16,AC$16)} -> 0.2 | AD22: {=_xlfn.IFS($C22<$Z$14,AD$14, $C22<$Z$15,AD$15, $C22<$Z$16,AD$16)} -> 0.05 | AE22: {=_xlfn.IFS($C22<$Z$14,AE$14, $C22<$Z$15,AE$15, $C22<$Z$16,AE$16)} -> 0.03
A23: 22 | B23: 0.71732593 | C23: =RAND() -> 0.88287925 | E23: {=_xlfn.IFS($C23<$D$14,E$14, $C23<$D$15,E$15, $C23<$D$16,E$16)} -> 0.07 | F23: {=_xlfn.IFS($C23<$D$14,F$14, $C23<$D$15,F$15, $C23<$D$16,F$16)} -> 0.05 | G23: {=_xlfn.IFS($C23<$D$14,G$14, $C23<$D$15,G$15, $C23<$D$16,G$16)} -> 0.05 | H23: {=_xlfn.IFS($C23<$D$14,H$14, $C23<$D$15,H$15, $C23<$D$16,H$16)} -> 0.05 | I23: {=_xlfn.IFS($C23<$D$14,I$14, $C23<$D$15,I$15, $C23<$D$16,I$16)} -> 0 | O23: {=_xlfn.IFS($C23<$D$14,O$14, $C23<$D$15,O$15, $C23<$D$16,O$16)} -> 0.06 | P23: {=_xlfn.IFS($C23<$D$14,P$14, $C23<$D$15,P$15, $C23<$D$16,P$16)} -> 0.05 | Q23: {=_xlfn.IFS($C23<$D$14,Q$14, $C23<$D$15,Q$15, $C23<$D$16,Q$16)} -> 0.05 | R23: {=_xlfn.IFS($C23<$D$14,R$14, $C23<$D$15,R$15, $C23<$D$16,R$16)} -> 0.06 | S23: {=_xlfn.IFS($C23<$D$14,S$14, $C23<$D$15,S$15, $C23<$D$16,S$16)} -> 0.04 | T23: {=_xlfn.IFS($C23<$D$14,T$14, $C23<$D$15,T$15, $C23<$D$16,T$16)} -> 0.04 | U23: {=_xlfn.IFS($C23<$D$14,U$14, $C23<$D$15,U$15, $C23<$D$16,U$16)} -> 0 | V23: {=_xlfn.IFS($C23<$D$14,V$14, $C23<$D$15,V$15, $C23<$D$16,V$16)} -> 15000 | AA23: {=_xlfn.IFS($C23<$Z$14,AA$14, $C23<$Z$15,AA$15, $C23<$Z$16,AA$16)} -> 0.12 | AB23: {=_xlfn.IFS($C23<$Z$14,AB$14, $C23<$Z$15,AB$15, $C23<$Z$16,AB$16)} -> 0.14 | AC23: {=_xlfn.IFS($C23<$Z$14,AC$14, $C23<$Z$15,AC$15, $C23<$Z$16,AC$16)} -> 0.16 | AD23: {=_xlfn.IFS($C23<$Z$14,AD$14, $C23<$Z$15,AD$15, $C23<$Z$16,AD$16)} -> 0.05 | AE23: {=_xlfn.IFS($C23<$Z$14,AE$14, $C23<$Z$15,AE$15, $C23<$Z$16,AE$16)} -> 0.03
A24: 23 | B24: 0.57865858 | C24: =RAND() -> 0.047902914 | E24: {=_xlfn.IFS($C24<$D$14,E$14, $C24<$D$15,E$15, $C24<$D$16,E$16)} -> 0.1 | F24: {=_xlfn.IFS($C24<$D$14,F$14, $C24<$D$15,F$15, $C24<$D$16,F$16)} -> 0.05 | G24: {=_xlfn.IFS($C24<$D$14,G$14, $C24<$D$15,G$15, $C24<$D$16,G$16)} -> 0.05 | H24: {=_xlfn.IFS($C24<$D$14,H$14, $C24<$D$15,H$15, $C24<$D$16,H$16)} -> 0.1 | I24: {=_xlfn.IFS($C24<$D$14,I$14, $C24<$D$15,I$15, $C24<$D$16,I$16)} -> 0 | O24: {=_xlfn.IFS($C24<$D$14,O$14, $C24<$D$15,O$15, $C24<$D$16,O$16)} -> 0.05 | P24: {=_xlfn.IFS($C24<$D$14,P$14, $C24<$D$15,P$15, $C24<$D$16,P$16)} -> 0.04 | Q24: {=_xlfn.IFS($C24<$D$14,Q$14, $C24<$D$15,Q$15, $C24<$D$16,Q$16)} -> 0.08 | R24: {=_xlfn.IFS($C24<$D$14,R$14, $C24<$D$15,R$15, $C24<$D$16,R$16)} -> 0.06 | S24: {=_xlfn.IFS($C24<$D$14,S$14, $C24<$D$15,S$15, $C24<$D$16,S$16)} -> 0.04 | T24: {=_xlfn.IFS($C24<$D$14,T$14, $C24<$D$15,T$15, $C24<$D$16,T$16)} -> 0.05 | U24: {=_xlfn.IFS($C24<$D$14,U$14, $C24<$D$15,U$15, $C24<$D$16,U$16)} -> 0 | V24: {=_xlfn.IFS($C24<$D$14,V$14, $C24<$D$15,V$15, $C24<$D$16,V$16)} -> 10000 | AA24: {=_xlfn.IFS($C24<$Z$14,AA$14, $C24<$Z$15,AA$15, $C24<$Z$16,AA$16)} -> 0.14 | AB24: {=_xlfn.IFS($C24<$Z$14,AB$14, $C24<$Z$15,AB$15, $C24<$Z$16,AB$16)} -> 0.16 | AC24: {=_xlfn.IFS($C24<$Z$14,AC$14, $C24<$Z$15,AC$15, $C24<$Z$16,AC$16)} -> 0.2 | AD24: {=_xlfn.IFS($C24<$Z$14,AD$14, $C24<$Z$15,AD$15, $C24<$Z$16,AD$16)} -> 0.05 | AE24: {=_xlfn.IFS($C24<$Z$14,AE$14, $C24<$Z$15,AE$15, $C24<$Z$16,AE$16)} -> 0.03
A25: 24 | B25: 0.94896113 | C25: =RAND() -> 0.31357845 | E25: {=_xlfn.IFS($C25<$D$14,E$14, $C25<$D$15,E$15, $C25<$D$16,E$16)} -> 0.1 | F25: {=_xlfn.IFS($C25<$D$14,F$14, $C25<$D$15,F$15, $C25<$D$16,F$16)} -> 0.05 | G25: {=_xlfn.IFS($C25<$D$14,G$14, $C25<$D$15,G$15, $C25<$D$16,G$16)} -> 0.05 | H25: {=_xlfn.IFS($C25<$D$14,H$14, $C25<$D$15,H$15, $C25<$D$16,H$16)} -> 0.1 | I25: {=_xlfn.IFS($C25<$D$14,I$14, $C25<$D$15,I$15, $C25<$D$16,I$16)} -> 0 | O25: {=_xlfn.IFS($C25<$D$14,O$14, $C25<$D$15,O$15, $C25<$D$16,O$16)} -> 0.05 | P25: {=_xlfn.IFS($C25<$D$14,P$14, $C25<$D$15,P$15, $C25<$D$16,P$16)} -> 0.04 | Q25: {=_xlfn.IFS($C25<$D$14,Q$14, $C25<$D$15,Q$15, $C25<$D$16,Q$16)} -> 0.08 | R25: {=_xlfn.IFS($C25<$D$14,R$14, $C25<$D$15,R$15, $C25<$D$16,R$16)} -> 0.06 | S25: {=_xlfn.IFS($C25<$D$14,S$14, $C25<$D$15,S$15, $C25<$D$16,S$16)} -> 0.04 | T25: {=_xlfn.IFS($C25<$D$14,T$14, $C25<$D$15,T$15, $C25<$D$16,T$16)} -> 0.05 | U25: {=_xlfn.IFS($C25<$D$14,U$14, $C25<$D$15,U$15, $C25<$D$16,U$16)} -> 0 | V25: {=_xlfn.IFS($C25<$D$14,V$14, $C25<$D$15,V$15, $C25<$D$16,V$16)} -> 10000 | AA25: {=_xlfn.IFS($C25<$Z$14,AA$14, $C25<$Z$15,AA$15, $C25<$Z$16,AA$16)} -> 0.14 | AB25: {=_xlfn.IFS($C25<$Z$14,AB$14, $C25<$Z$15,AB$15, $C25<$Z$16,AB$16)} -> 0.16 | AC25: {=_xlfn.IFS($C25<$Z$14,AC$14, $C25<$Z$15,AC$15, $C25<$Z$16,AC$16)} -> 0.2 | AD25: {=_xlfn.IFS($C25<$Z$14,AD$14, $C25<$Z$15,AD$15, $C25<$Z$16,AD$16)} -> 0.05 | AE25: {=_xlfn.IFS($C25<$Z$14,AE$14, $C25<$Z$15,AE$15, $C25<$Z$16,AE$16)} -> 0.03
A26: 25 | B26: 0.36965764 | C26: =RAND() -> 0.97183118 | E26: {=_xlfn.IFS($C26<$D$14,E$14, $C26<$D$15,E$15, $C26<$D$16,E$16)} -> 0.04 | F26: {=_xlfn.IFS($C26<$D$14,F$14, $C26<$D$15,F$15, $C26<$D$16,F$16)} -> 0.05 | G26: {=_xlfn.IFS($C26<$D$14,G$14, $C26<$D$15,G$15, $C26<$D$16,G$16)} -> 0.05 | H26: {=_xlfn.IFS($C26<$D$14,H$14, $C26<$D$15,H$15, $C26<$D$16,H$16)} -> 0.01 | I26: {=_xlfn.IFS($C26<$D$14,I$14, $C26<$D$15,I$15, $C26<$D$16,I$16)} -> 0 | O26: {=_xlfn.IFS($C26<$D$14,O$14, $C26<$D$15,O$15, $C26<$D$16,O$16)} -> 0.08 | P26: {=_xlfn.IFS($C26<$D$14,P$14, $C26<$D$15,P$15, $C26<$D$16,P$16)} -> 0.07 | Q26: {=_xlfn.IFS($C26<$D$14,Q$14, $C26<$D$15,Q$15, $C26<$D$16,Q$16)} -> 0.1 | R26: {=_xlfn.IFS($C26<$D$14,R$14, $C26<$D$15,R$15, $C26<$D$16,R$16)} -> 0.06 | S26: {=_xlfn.IFS($C26<$D$14,S$14, $C26<$D$15,S$15, $C26<$D$16,S$16)} -> 0.04 | T26: {=_xlfn.IFS($C26<$D$14,T$14, $C26<$D$15,T$15, $C26<$D$16,T$16)} -> 0.08 | U26: {=_xlfn.IFS($C26<$D$14,U$14, $C26<$D$15,U$15, $C26<$D$16,U$16)} -> 0 | V26: {=_xlfn.IFS($C26<$D$14,V$14, $C26<$D$15,V$15, $C26<$D$16,V$16)} -> 30000 | AA26: {=_xlfn.IFS($C26<$Z$14,AA$14, $C26<$Z$15,AA$15, $C26<$Z$16,AA$16)} -> 0.09 | AB26: {=_xlfn.IFS($C26<$Z$14,AB$14, $C26<$Z$15,AB$15, $C26<$Z$16,AB$16)} -> 0.12 | AC26: {=_xlfn.IFS($C26<$Z$14,AC$14, $C26<$Z$15,AC$15, $C26<$Z$16,AC$16)} -> 0.14 | AD26: {=_xlfn.IFS($C26<$Z$14,AD$14, $C26<$Z$15,AD$15, $C26<$Z$16,AD$16)} -> 0.05 | AE26: {=_xlfn.IFS($C26<$Z$14,AE$14, $C26<$Z$15,AE$15, $C26<$Z$16,AE$16)} -> 0.03
A27: 26 | B27: 0.77762074 | C27: =RAND() -> 0.40933402 | E27: {=_xlfn.IFS($C27<$D$14,E$14, $C27<$D$15,E$15, $C27<$D$16,E$16)} -> 0.1 | F27: {=_xlfn.IFS($C27<$D$14,F$14, $C27<$D$15,F$15, $C27<$D$16,F$16)} -> 0.05 | G27: {=_xlfn.IFS($C27<$D$14,G$14, $C27<$D$15,G$15, $C27<$D$16,G$16)} -> 0.05 | H27: {=_xlfn.IFS($C27<$D$14,H$14, $C27<$D$15,H$15, $C27<$D$16,H$16)} -> 0.1 | I27: {=_xlfn.IFS($C27<$D$14,I$14, $C27<$D$15,I$15, $C27<$D$16,I$16)} -> 0 | O27: {=_xlfn.IFS($C27<$D$14,O$14, $C27<$D$15,O$15, $C27<$D$16,O$16)} -> 0.05 | P27: {=_xlfn.IFS($C27<$D$14,P$14, $C27<$D$15,P$15, $C27<$D$16,P$16)} -> 0.04 | Q27: {=_xlfn.IFS($C27<$D$14,Q$14, $C27<$D$15,Q$15, $C27<$D$16,Q$16)} -> 0.08 | R27: {=_xlfn.IFS($C27<$D$14,R$14, $C27<$D$15,R$15, $C27<$D$16,R$16)} -> 0.06 | S27: {=_xlfn.IFS($C27<$D$14,S$14, $C27<$D$15,S$15, $C27<$D$16,S$16)} -> 0.04 | T27: {=_xlfn.IFS($C27<$D$14,T$14, $C27<$D$15,T$15, $C27<$D$16,T$16)} -> 0.05 | U27: {=_xlfn.IFS($C27<$D$14,U$14, $C27<$D$15,U$15, $C27<$D$16,U$16)} -> 0 | V27: {=_xlfn.IFS($C27<$D$14,V$14, $C27<$D$15,V$15, $C27<$D$16,V$16)} -> 10000 | AA27: {=_xlfn.IFS($C27<$Z$14,AA$14, $C27<$Z$15,AA$15, $C27<$Z$16,AA$16)} -> 0.14 | AB27: {=_xlfn.IFS($C27<$Z$14,AB$14, $C27<$Z$15,AB$15, $C27<$Z$16,AB$16)} -> 0.16 | AC27: {=_xlfn.IFS($C27<$Z$14,AC$14, $C27<$Z$15,AC$15, $C27<$Z$16,AC$16)} -> 0.2 | AD27: {=_xlfn.IFS($C27<$Z$14,AD$14, $C27<$Z$15,AD$15, $C27<$Z$16,AD$16)} -> 0.05 | AE27: {=_xlfn.IFS($C27<$Z$14,AE$14, $C27<$Z$15,AE$15, $C27<$Z$16,AE$16)} -> 0.03
A28: 27 | B28: 0.022391029 | C28: =RAND() -> 0.72790364 | E28: {=_xlfn.IFS($C28<$D$14,E$14, $C28<$D$15,E$15, $C28<$D$16,E$16)} -> 0.1 | F28: {=_xlfn.IFS($C28<$D$14,F$14, $C28<$D$15,F$15, $C28<$D$16,F$16)} -> 0.05 | G28: {=_xlfn.IFS($C28<$D$14,G$14, $C28<$D$15,G$15, $C28<$D$16,G$16)} -> 0.05 | H28: {=_xlfn.IFS($C28<$D$14,H$14, $C28<$D$15,H$15, $C28<$D$16,H$16)} -> 0.1 | I28: {=_xlfn.IFS($C28<$D$14,I$14, $C28<$D$15,I$15, $C28<$D$16,I$16)} -> 0 | O28: {=_xlfn.IFS($C28<$D$14,O$14, $C28<$D$15,O$15, $C28<$D$16,O$16)} -> 0.05 | P28: {=_xlfn.IFS($C28<$D$14,P$14, $C28<$D$15,P$15, $C28<$D$16,P$16)} -> 0.04 | Q28: {=_xlfn.IFS($C28<$D$14,Q$14, $C28<$D$15,Q$15, $C28<$D$16,Q$16)} -> 0.08 | R28: {=_xlfn.IFS($C28<$D$14,R$14, $C28<$D$15,R$15, $C28<$D$16,R$16)} -> 0.06 | S28: {=_xlfn.IFS($C28<$D$14,S$14, $C28<$D$15,S$15, $C28<$D$16,S$16)} -> 0.04 | T28: {=_xlfn.IFS($C28<$D$14,T$14, $C28<$D$15,T$15, $C28<$D$16,T$16)} -> 0.05 | U28: {=_xlfn.IFS($C28<$D$14,U$14, $C28<$D$15,U$15, $C28<$D$16,U$16)} -> 0 | V28: {=_xlfn.IFS($C28<$D$14,V$14, $C28<$D$15,V$15, $C28<$D$16,V$16)} -> 10000 | AA28: {=_xlfn.IFS($C28<$Z$14,AA$14, $C28<$Z$15,AA$15, $C28<$Z$16,AA$16)} -> 0.14 | AB28: {=_xlfn.IFS($C28<$Z$14,AB$14, $C28<$Z$15,AB$15, $C28<$Z$16,AB$16)} -> 0.16 | AC28: {=_xlfn.IFS($C28<$Z$14,AC$14, $C28<$Z$15,AC$15, $C28<$Z$16,AC$16)} -> 0.2 | AD28: {=_xlfn.IFS($C28<$Z$14,AD$14, $C28<$Z$15,AD$15, $C28<$Z$16,AD$16)} -> 0.05 | AE28: {=_xlfn.IFS($C28<$Z$14,AE$14, $C28<$Z$15,AE$15, $C28<$Z$16,AE$16)} -> 0.03
A29: 28 | B29: 0.60634937 | C29: =RAND() -> 0.67431708 | E29: {=_xlfn.IFS($C29<$D$14,E$14, $C29<$D$15,E$15, $C29<$D$16,E$16)} -> 0.1 | F29: {=_xlfn.IFS($C29<$D$14,F$14, $C29<$D$15,F$15, $C29<$D$16,F$16)} -> 0.05 | G29: {=_xlfn.IFS($C29<$D$14,G$14, $C29<$D$15,G$15, $C29<$D$16,G$16)} -> 0.05 | H29: {=_xlfn.IFS($C29<$D$14,H$14, $C29<$D$15,H$15, $C29<$D$16,H$16)} -> 0.1 | I29: {=_xlfn.IFS($C29<$D$14,I$14, $C29<$D$15,I$15, $C29<$D$16,I$16)} -> 0 | O29: {=_xlfn.IFS($C29<$D$14,O$14, $C29<$D$15,O$15, $C29<$D$16,O$16)} -> 0.05 | P29: {=_xlfn.IFS($C29<$D$14,P$14, $C29<$D$15,P$15, $C29<$D$16,P$16)} -> 0.04 | Q29: {=_xlfn.IFS($C29<$D$14,Q$14, $C29<$D$15,Q$15, $C29<$D$16,Q$16)} -> 0.08 | R29: {=_xlfn.IFS($C29<$D$14,R$14, $C29<$D$15,R$15, $C29<$D$16,R$16)} -> 0.06 | S29: {=_xlfn.IFS($C29<$D$14,S$14, $C29<$D$15,S$15, $C29<$D$16,S$16)} -> 0.04 | T29: {=_xlfn.IFS($C29<$D$14,T$14, $C29<$D$15,T$15, $C29<$D$16,T$16)} -> 0.05 | U29: {=_xlfn.IFS($C29<$D$14,U$14, $C29<$D$15,U$15, $C29<$D$16,U$16)} -> 0 | V29: {=_xlfn.IFS($C29<$D$14,V$14, $C29<$D$15,V$15, $C29<$D$16,V$16)} -> 10000 | AA29: {=_xlfn.IFS($C29<$Z$14,AA$14, $C29<$Z$15,AA$15, $C29<$Z$16,AA$16)} -> 0.14 | AB29: {=_xlfn.IFS($C29<$Z$14,AB$14, $C29<$Z$15,AB$15, $C29<$Z$16,AB$16)} -> 0.16 | AC29: {=_xlfn.IFS($C29<$Z$14,AC$14, $C29<$Z$15,AC$15, $C29<$Z$16,AC$16)} -> 0.2 | AD29: {=_xlfn.IFS($C29<$Z$14,AD$14, $C29<$Z$15,AD$15, $C29<$Z$16,AD$16)} -> 0.05 | AE29: {=_xlfn.IFS($C29<$Z$14,AE$14, $C29<$Z$15,AE$15, $C29<$Z$16,AE$16)} -> 0.03
A30: 29 | B30: 0.46050695 | C30: =RAND() -> 0.70938432 | E30: {=_xlfn.IFS($C30<$D$14,E$14, $C30<$D$15,E$15, $C30<$D$16,E$16)} -> 0.1 | F30: {=_xlfn.IFS($C30<$D$14,F$14, $C30<$D$15,F$15, $C30<$D$16,F$16)} -> 0.05 | G30: {=_xlfn.IFS($C30<$D$14,G$14, $C30<$D$15,G$15, $C30<$D$16,G$16)} -> 0.05 | H30: {=_xlfn.IFS($C30<$D$14,H$14, $C30<$D$15,H$15, $C30<$D$16,H$16)} -> 0.1 | I30: {=_xlfn.IFS($C30<$D$14,I$14, $C30<$D$15,I$15, $C30<$D$16,I$16)} -> 0 | O30: {=_xlfn.IFS($C30<$D$14,O$14, $C30<$D$15,O$15, $C30<$D$16,O$16)} -> 0.05 | P30: {=_xlfn.IFS($C30<$D$14,P$14, $C30<$D$15,P$15, $C30<$D$16,P$16)} -> 0.04 | Q30: {=_xlfn.IFS($C30<$D$14,Q$14, $C30<$D$15,Q$15, $C30<$D$16,Q$16)} -> 0.08 | R30: {=_xlfn.IFS($C30<$D$14,R$14, $C30<$D$15,R$15, $C30<$D$16,R$16)} -> 0.06 | S30: {=_xlfn.IFS($C30<$D$14,S$14, $C30<$D$15,S$15, $C30<$D$16,S$16)} -> 0.04 | T30: {=_xlfn.IFS($C30<$D$14,T$14, $C30<$D$15,T$15, $C30<$D$16,T$16)} -> 0.05 | U30: {=_xlfn.IFS($C30<$D$14,U$14, $C30<$D$15,U$15, $C30<$D$16,U$16)} -> 0 | V30: {=_xlfn.IFS($C30<$D$14,V$14, $C30<$D$15,V$15, $C30<$D$16,V$16)} -> 10000 | AA30: {=_xlfn.IFS($C30<$Z$14,AA$14, $C30<$Z$15,AA$15, $C30<$Z$16,AA$16)} -> 0.14 | AB30: {=_xlfn.IFS($C30<$Z$14,AB$14, $C30<$Z$15,AB$15, $C30<$Z$16,AB$16)} -> 0.16 | AC30: {=_xlfn.IFS($C30<$Z$14,AC$14, $C30<$Z$15,AC$15, $C30<$Z$16,AC$16)} -> 0.2 | AD30: {=_xlfn.IFS($C30<$Z$14,AD$14, $C30<$Z$15,AD$15, $C30<$Z$16,AD$16)} -> 0.05 | AE30: {=_xlfn.IFS($C30<$Z$14,AE$14, $C30<$Z$15,AE$15, $C30<$Z$16,AE$16)} -> 0.03
A31: 30 | B31: 0.60175563 | C31: =RAND() -> 0.87310294 | E31: {=_xlfn.IFS($C31<$D$14,E$14, $C31<$D$15,E$15, $C31<$D$16,E$16)} -> 0.07 | F31: {=_xlfn.IFS($C31<$D$14,F$14, $C31<$D$15,F$15, $C31<$D$16,F$16)} -> 0.05 | G31: {=_xlfn.IFS($C31<$D$14,G$14, $C31<$D$15,G$15, $C31<$D$16,G$16)} -> 0.05 | H31: {=_xlfn.IFS($C31<$D$14,H$14, $C31<$D$15,H$15, $C31<$D$16,H$16)} -> 0.05 | I31: {=_xlfn.IFS($C31<$D$14,I$14, $C31<$D$15,I$15, $C31<$D$16,I$16)} -> 0 | O31: {=_xlfn.IFS($C31<$D$14,O$14, $C31<$D$15,O$15, $C31<$D$16,O$16)} -> 0.06 | P31: {=_xlfn.IFS($C31<$D$14,P$14, $C31<$D$15,P$15, $C31<$D$16,P$16)} -> 0.05 | Q31: {=_xlfn.IFS($C31<$D$14,Q$14, $C31<$D$15,Q$15, $C31<$D$16,Q$16)} -> 0.05 | R31: {=_xlfn.IFS($C31<$D$14,R$14, $C31<$D$15,R$15, $C31<$D$16,R$16)} -> 0.06 | S31: {=_xlfn.IFS($C31<$D$14,S$14, $C31<$D$15,S$15, $C31<$D$16,S$16)} -> 0.04 | T31: {=_xlfn.IFS($C31<$D$14,T$14, $C31<$D$15,T$15, $C31<$D$16,T$16)} -> 0.04 | U31: {=_xlfn.IFS($C31<$D$14,U$14, $C31<$D$15,U$15, $C31<$D$16,U$16)} -> 0 | V31: {=_xlfn.IFS($C31<$D$14,V$14, $C31<$D$15,V$15, $C31<$D$16,V$16)} -> 15000 | AA31: {=_xlfn.IFS($C31<$Z$14,AA$14, $C31<$Z$15,AA$15, $C31<$Z$16,AA$16)} -> 0.12 | AB31: {=_xlfn.IFS($C31<$Z$14,AB$14, $C31<$Z$15,AB$15, $C31<$Z$16,AB$16)} -> 0.14 | AC31: {=_xlfn.IFS($C31<$Z$14,AC$14, $C31<$Z$15,AC$15, $C31<$Z$16,AC$16)} -> 0.16 | AD31: {=_xlfn.IFS($C31<$Z$14,AD$14, $C31<$Z$15,AD$15, $C31<$Z$16,AD$16)} -> 0.05 | AE31: {=_xlfn.IFS($C31<$Z$14,AE$14, $C31<$Z$15,AE$15, $C31<$Z$16,AE$16)} -> 0.03
A32: 31 | B32: 0.83464744 | C32: =RAND() -> 0.34060992 | E32: {=_xlfn.IFS($C32<$D$14,E$14, $C32<$D$15,E$15, $C32<$D$16,E$16)} -> 0.1 | F32: {=_xlfn.IFS($C32<$D$14,F$14, $C32<$D$15,F$15, $C32<$D$16,F$16)} -> 0.05 | G32: {=_xlfn.IFS($C32<$D$14,G$14, $C32<$D$15,G$15, $C32<$D$16,G$16)} -> 0.05 | H32: {=_xlfn.IFS($C32<$D$14,H$14, $C32<$D$15,H$15, $C32<$D$16,H$16)} -> 0.1 | I32: {=_xlfn.IFS($C32<$D$14,I$14, $C32<$D$15,I$15, $C32<$D$16,I$16)} -> 0 | O32: {=_xlfn.IFS($C32<$D$14,O$14, $C32<$D$15,O$15, $C32<$D$16,O$16)} -> 0.05 | P32: {=_xlfn.IFS($C32<$D$14,P$14, $C32<$D$15,P$15, $C32<$D$16,P$16)} -> 0.04 | Q32: {=_xlfn.IFS($C32<$D$14,Q$14, $C32<$D$15,Q$15, $C32<$D$16,Q$16)} -> 0.08 | R32: {=_xlfn.IFS($C32<$D$14,R$14, $C32<$D$15,R$15, $C32<$D$16,R$16)} -> 0.06 | S32: {=_xlfn.IFS($C32<$D$14,S$14, $C32<$D$15,S$15, $C32<$D$16,S$16)} -> 0.04 | T32: {=_xlfn.IFS($C32<$D$14,T$14, $C32<$D$15,T$15, $C32<$D$16,T$16)} -> 0.05 | U32: {=_xlfn.IFS($C32<$D$14,U$14, $C32<$D$15,U$15, $C32<$D$16,U$16)} -> 0 | V32: {=_xlfn.IFS($C32<$D$14,V$14, $C32<$D$15,V$15, $C32<$D$16,V$16)} -> 10000 | AA32: {=_xlfn.IFS($C32<$Z$14,AA$14, $C32<$Z$15,AA$15, $C32<$Z$16,AA$16)} -> 0.14 | AB32: {=_xlfn.IFS($C32<$Z$14,AB$14, $C32<$Z$15,AB$15, $C32<$Z$16,AB$16)} -> 0.16 | AC32: {=_xlfn.IFS($C32<$Z$14,AC$14, $C32<$Z$15,AC$15, $C32<$Z$16,AC$16)} -> 0.2 | AD32: {=_xlfn.IFS($C32<$Z$14,AD$14, $C32<$Z$15,AD$15, $C32<$Z$16,AD$16)} -> 0.05 | AE32: {=_xlfn.IFS($C32<$Z$14,AE$14, $C32<$Z$15,AE$15, $C32<$Z$16,AE$16)} -> 0.03
A33: 32 | B33: 0.69922046 | C33: =RAND() -> 0.034965093 | E33: {=_xlfn.IFS($C33<$D$14,E$14, $C33<$D$15,E$15, $C33<$D$16,E$16)} -> 0.1 | F33: {=_xlfn.IFS($C33<$D$14,F$14, $C33<$D$15,F$15, $C33<$D$16,F$16)} -> 0.05 | G33: {=_xlfn.IFS($C33<$D$14,G$14, $C33<$D$15,G$15, $C33<$D$16,G$16)} -> 0.05 | H33: {=_xlfn.IFS($C33<$D$14,H$14, $C33<$D$15,H$15, $C33<$D$16,H$16)} -> 0.1 | I33: {=_xlfn.IFS($C33<$D$14,I$14, $C33<$D$15,I$15, $C33<$D$16,I$16)} -> 0 | O33: {=_xlfn.IFS($C33<$D$14,O$14, $C33<$D$15,O$15, $C33<$D$16,O$16)} -> 0.05 | P33: {=_xlfn.IFS($C33<$D$14,P$14, $C33<$D$15,P$15, $C33<$D$16,P$16)} -> 0.04 | Q33: {=_xlfn.IFS($C33<$D$14,Q$14, $C33<$D$15,Q$15, $C33<$D$16,Q$16)} -> 0.08 | R33: {=_xlfn.IFS($C33<$D$14,R$14, $C33<$D$15,R$15, $C33<$D$16,R$16)} -> 0.06 | S33: {=_xlfn.IFS($C33<$D$14,S$14, $C33<$D$15,S$15, $C33<$D$16,S$16)} -> 0.04 | T33: {=_xlfn.IFS($C33<$D$14,T$14, $C33<$D$15,T$15, $C33<$D$16,T$16)} -> 0.05 | U33: {=_xlfn.IFS($C33<$D$14,U$14, $C33<$D$15,U$15, $C33<$D$16,U$16)} -> 0 | V33: {=_xlfn.IFS($C33<$D$14,V$14, $C33<$D$15,V$15, $C33<$D$16,V$16)} -> 10000 | AA33: {=_xlfn.IFS($C33<$Z$14,AA$14, $C33<$Z$15,AA$15, $C33<$Z$16,AA$16)} -> 0.14 | AB33: {=_xlfn.IFS($C33<$Z$14,AB$14, $C33<$Z$15,AB$15, $C33<$Z$16,AB$16)} -> 0.16 | AC33: {=_xlfn.IFS($C33<$Z$14,AC$14, $C33<$Z$15,AC$15, $C33<$Z$16,AC$16)} -> 0.2 | AD33: {=_xlfn.IFS($C33<$Z$14,AD$14, $C33<$Z$15,AD$15, $C33<$Z$16,AD$16)} -> 0.05 | AE33: {=_xlfn.IFS($C33<$Z$14,AE$14, $C33<$Z$15,AE$15, $C33<$Z$16,AE$16)} -> 0.03
... A55: 54 | B55: 0.35616888 | C55: =RAND() -> 0.62523235 | E55: {=_xlfn.IFS($C55<$D$14,E$14, $C55<$D$15,E$15, $C55<$D$16,E$16)} -> 0.1 | F55: {=_xlfn.IFS($C55<$D$14,F$14, $C55<$D$15,F$15, $C55<$D$16,F$16)} -> 0.05 | G55: {=_xlfn.IFS($C55<$D$14,G$14, $C55<$D$15,G$15, $C55<$D$16,G$16)} -> 0.05 | H55: {=_xlfn.IFS($C55<$D$14,H$14, $C55<$D$15,H$15, $C55<$D$16,H$16)} -> 0.1 | I55: {=_xlfn.IFS($C55<$D$14,I$14, $C55<$D$15,I$15, $C55<$D$16,I$16)} -> 0 | O55: {=_xlfn.IFS($C55<$D$14,O$14, $C55<$D$15,O$15, $C55<$D$16,O$16)} -> 0.05 | P55: {=_xlfn.IFS($C55<$D$14,P$14, $C55<$D$15,P$15, $C55<$D$16,P$16)} -> 0.04 | Q55: {=_xlfn.IFS($C55<$D$14,Q$14, $C55<$D$15,Q$15, $C55<$D$16,Q$16)} -> 0.08 | R55: {=_xlfn.IFS($C55<$D$14,R$14, $C55<$D$15,R$15, $C55<$D$16,R$16)} -> 0.06 | S55: {=_xlfn.IFS($C55<$D$14,S$14, $C55<$D$15,S$15, $C55<$D$16,S$16)} -> 0.04 | T55: {=_xlfn.IFS($C55<$D$14,T$14, $C55<$D$15,T$15, $C55<$D$16,T$16)} -> 0.05 | U55: {=_xlfn.IFS($C55<$D$14,U$14, $C55<$D$15,U$15, $C55<$D$16,U$16)} -> 0 | V55: {=_xlfn.IFS($C55<$D$14,V$14, $C55<$D$15,V$15, $C55<$D$16,V$16)} -> 10000 | AA55: {=_xlfn.IFS($C55<$Z$14,AA$14, $C55<$Z$15,AA$15, $C55<$Z$16,AA$16)} -> 0.14 | AB55: {=_xlfn.IFS($C55<$Z$14,AB$14, $C55<$Z$15,AB$15, $C55<$Z$16,AB$16)} -> 0.16 | AC55: {=_xlfn.IFS($C55<$Z$14,AC$14, $C55<$Z$15,AC$15, $C55<$Z$16,AC$16)} -> 0.2 | AD55: {=_xlfn.IFS($C55<$Z$14,AD$14, $C55<$Z$15,AD$15, $C55<$Z$16,AD$16)} -> 0.05 | AE55: {=_xlfn.IFS($C55<$Z$14,AE$14, $C55<$Z$15,AE$15, $C55<$Z$16,AE$16)} -> 0.03
B56: 0.65810393 | C56: =RAND() -> 0.60688739 | E56: {=_xlfn.IFS($C56<$D$14,E$14, $C56<$D$15,E$15, $C56<$D$16,E$16)} -> 0.1 | F56: {=_xlfn.IFS($C56<$D$14,F$14, $C56<$D$15,F$15, $C56<$D$16,F$16)} -> 0.05 | G56: {=_xlfn.IFS($C56<$D$14,G$14, $C56<$D$15,G$15, $C56<$D$16,G$16)} -> 0.05 | H56: {=_xlfn.IFS($C56<$D$14,H$14, $C56<$D$15,H$15, $C56<$D$16,H$16)} -> 0.1 | I56: {=_xlfn.IFS($C56<$D$14,I$14, $C56<$D$15,I$15, $C56<$D$16,I$16)} -> 0 | O56: {=_xlfn.IFS($C56<$D$14,O$14, $C56<$D$15,O$15, $C56<$D$16,O$16)} -> 0.05 | P56: {=_xlfn.IFS($C56<$D$14,P$14, $C56<$D$15,P$15, $C56<$D$16,P$16)} -> 0.04 | Q56: {=_xlfn.IFS($C56<$D$14,Q$14, $C56<$D$15,Q$15, $C56<$D$16,Q$16)} -> 0.08 | R56: {=_xlfn.IFS($C56<$D$14,R$14, $C56<$D$15,R$15, $C56<$D$16,R$16)} -> 0.06 | S56: {=_xlfn.IFS($C56<$D$14,S$14, $C56<$D$15,S$15, $C56<$D$16,S$16)} -> 0.04 | T56: {=_xlfn.IFS($C56<$D$14,T$14, $C56<$D$15,T$15, $C56<$D$16,T$16)} -> 0.05 | U56: {=_xlfn.IFS($C56<$D$14,U$14, $C56<$D$15,U$15, $C56<$D$16,U$16)} -> 0 | V56: {=_xlfn.IFS($C56<$D$14,V$14, $C56<$D$15,V$15, $C56<$D$16,V$16)} -> 10000 | AA56: {=_xlfn.IFS($C56<$Z$14,AA$14, $C56<$Z$15,AA$15, $C56<$Z$16,AA$16)} -> 0.14 | AB56: {=_xlfn.IFS($C56<$Z$14,AB$14, $C56<$Z$15,AB$15, $C56<$Z$16,AB$16)} -> 0.16 | AC56: {=_xlfn.IFS($C56<$Z$14,AC$14, $C56<$Z$15,AC$15, $C56<$Z$16,AC$16)} -> 0.2 | AD56: {=_xlfn.IFS($C56<$Z$14,AD$14, $C56<$Z$15,AD$15, $C56<$Z$16,AD$16)} -> 0.05 | AE56: {=_xlfn.IFS($C56<$Z$14,AE$14, $C56<$Z$15,AE$15, $C56<$Z$16,AE$16)} -> 0.03
B57: 0.63244219 | C57: =RAND() -> 0.21347119 | E57: {=_xlfn.IFS($C57<$D$14,E$14, $C57<$D$15,E$15, $C57<$D$16,E$16)} -> 0.1 | F57: {=_xlfn.IFS($C57<$D$14,F$14, $C57<$D$15,F$15, $C57<$D$16,F$16)} -> 0.05 | G57: {=_xlfn.IFS($C57<$D$14,G$14, $C57<$D$15,G$15, $C57<$D$16,G$16)} -> 0.05 | H57: {=_xlfn.IFS($C57<$D$14,H$14, $C57<$D$15,H$15, $C57<$D$16,H$16)} -> 0.1 | I57: {=_xlfn.IFS($C57<$D$14,I$14, $C57<$D$15,I$15, $C57<$D$16,I$16)} -> 0 | O57: {=_xlfn.IFS($C57<$D$14,O$14, $C57<$D$15,O$15, $C57<$D$16,O$16)} -> 0.05 | P57: {=_xlfn.IFS($C57<$D$14,P$14, $C57<$D$15,P$15, $C57<$D$16,P$16)} -> 0.04 | Q57: {=_xlfn.IFS($C57<$D$14,Q$14, $C57<$D$15,Q$15, $C57<$D$16,Q$16)} -> 0.08 | R57: {=_xlfn.IFS($C57<$D$14,R$14, $C57<$D$15,R$15, $C57<$D$16,R$16)} -> 0.06 | S57: {=_xlfn.IFS($C57<$D$14,S$14, $C57<$D$15,S$15, $C57<$D$16,S$16)} -> 0.04 | T57: {=_xlfn.IFS($C57<$D$14,T$14, $C57<$D$15,T$15, $C57<$D$16,T$16)} -> 0.05 | U57: {=_xlfn.IFS($C57<$D$14,U$14, $C57<$D$15,U$15, $C57<$D$16,U$16)} -> 0 | V57: {=_xlfn.IFS($C57<$D$14,V$14, $C57<$D$15,V$15, $C57<$D$16,V$16)} -> 10000 | AA57: {=_xlfn.IFS($C57<$Z$14,AA$14, $C57<$Z$15,AA$15, $C57<$Z$16,AA$16)} -> 0.14 | AB57: {=_xlfn.IFS($C57<$Z$14,AB$14, $C57<$Z$15,AB$15, $C57<$Z$16,AB$16)} -> 0.16 | AC57: {=_xlfn.IFS($C57<$Z$14,AC$14, $C57<$Z$15,AC$15, $C57<$Z$16,AC$16)} -> 0.2 | AD57: {=_xlfn.IFS($C57<$Z$14,AD$14, $C57<$Z$15,AD$15, $C57<$Z$16,AD$16)} -> 0.05 | AE57: {=_xlfn.IFS($C57<$Z$14,AE$14, $C57<$Z$15,AE$15, $C57<$Z$16,AE$16)} -> 0.03
B58: 0.098462824 | C58: =RAND() -> 0.27180056 | E58: {=_xlfn.IFS($C58<$D$14,E$14, $C58<$D$15,E$15, $C58<$D$16,E$16)} -> 0.1 | F58: {=_xlfn.IFS($C58<$D$14,F$14, $C58<$D$15,F$15, $C58<$D$16,F$16)} -> 0.05 | G58: {=_xlfn.IFS($C58<$D$14,G$14, $C58<$D$15,G$15, $C58<$D$16,G$16)} -> 0.05 | H58: {=_xlfn.IFS($C58<$D$14,H$14, $C58<$D$15,H$15, $C58<$D$16,H$16)} -> 0.1 | I58: {=_xlfn.IFS($C58<$D$14,I$14, $C58<$D$15,I$15, $C58<$D$16,I$16)} -> 0 | O58: {=_xlfn.IFS($C58<$D$14,O$14, $C58<$D$15,O$15, $C58<$D$16,O$16)} -> 0.05 | P58: {=_xlfn.IFS($C58<$D$14,P$14, $C58<$D$15,P$15, $C58<$D$16,P$16)} -> 0.04 | Q58: {=_xlfn.IFS($C58<$D$14,Q$14, $C58<$D$15,Q$15, $C58<$D$16,Q$16)} -> 0.08 | R58: {=_xlfn.IFS($C58<$D$14,R$14, $C58<$D$15,R$15, $C58<$D$16,R$16)} -> 0.06 | S58: {=_xlfn.IFS($C58<$D$14,S$14, $C58<$D$15,S$15, $C58<$D$16,S$16)} -> 0.04 | T58: {=_xlfn.IFS($C58<$D$14,T$14, $C58<$D$15,T$15, $C58<$D$16,T$16)} -> 0.05 | U58: {=_xlfn.IFS($C58<$D$14,U$14, $C58<$D$15,U$15, $C58<$D$16,U$16)} -> 0 | V58: {=_xlfn.IFS($C58<$D$14,V$14, $C58<$D$15,V$15, $C58<$D$16,V$16)} -> 10000 | AA58: {=_xlfn.IFS($C58<$Z$14,AA$14, $C58<$Z$15,AA$15, $C58<$Z$16,AA$16)} -> 0.14 | AB58: {=_xlfn.IFS($C58<$Z$14,AB$14, $C58<$Z$15,AB$15, $C58<$Z$16,AB$16)} -> 0.16 | AC58: {=_xlfn.IFS($C58<$Z$14,AC$14, $C58<$Z$15,AC$15, $C58<$Z$16,AC$16)} -> 0.2 | AD58: {=_xlfn.IFS($C58<$Z$14,AD$14, $C58<$Z$15,AD$15, $C58<$Z$16,AD$16)} -> 0.05 | AE58: {=_xlfn.IFS($C58<$Z$14,AE$14, $C58<$Z$15,AE$15, $C58<$Z$16,AE$16)} -> 0.03
B59: 0.25654279 | C59: =RAND() -> 0.34044587 | E59: {=_xlfn.IFS($C59<$D$14,E$14, $C59<$D$15,E$15, $C59<$D$16,E$16)} -> 0.1 | F59: {=_xlfn.IFS($C59<$D$14,F$14, $C59<$D$15,F$15, $C59<$D$16,F$16)} -> 0.05 | G59: {=_xlfn.IFS($C59<$D$14,G$14, $C59<$D$15,G$15, $C59<$D$16,G$16)} -> 0.05 | H59: {=_xlfn.IFS($C59<$D$14,H$14, $C59<$D$15,H$15, $C59<$D$16,H$16)} -> 0.1 | I59: {=_xlfn.IFS($C59<$D$14,I$14, $C59<$D$15,I$15, $C59<$D$16,I$16)} -> 0 | O59: {=_xlfn.IFS($C59<$D$14,O$14, $C59<$D$15,O$15, $C59<$D$16,O$16)} -> 0.05 | P59: {=_xlfn.IFS($C59<$D$14,P$14, $C59<$D$15,P$15, $C59<$D$16,P$16)} -> 0.04 | Q59: {=_xlfn.IFS($C59<$D$14,Q$14, $C59<$D$15,Q$15, $C59<$D$16,Q$16)} -> 0.08 | R59: {=_xlfn.IFS($C59<$D$14,R$14, $C59<$D$15,R$15, $C59<$D$16,R$16)} -> 0.06 | S59: {=_xlfn.IFS($C59<$D$14,S$14, $C59<$D$15,S$15, $C59<$D$16,S$16)} -> 0.04 | T59: {=_xlfn.IFS($C59<$D$14,T$14, $C59<$D$15,T$15, $C59<$D$16,T$16)} -> 0.05 | U59: {=_xlfn.IFS($C59<$D$14,U$14, $C59<$D$15,U$15, $C59<$D$16,U$16)} -> 0 | V59: {=_xlfn.IFS($C59<$D$14,V$14, $C59<$D$15,V$15, $C59<$D$16,V$16)} -> 10000 | AA59: {=_xlfn.IFS($C59<$Z$14,AA$14, $C59<$Z$15,AA$15, $C59<$Z$16,AA$16)} -> 0.14 | AB59: {=_xlfn.IFS($C59<$Z$14,AB$14, $C59<$Z$15,AB$15, $C59<$Z$16,AB$16)} -> 0.16 | AC59: {=_xlfn.IFS($C59<$Z$14,AC$14, $C59<$Z$15,AC$15, $C59<$Z$16,AC$16)} -> 0.2 | AD59: {=_xlfn.IFS($C59<$Z$14,AD$14, $C59<$Z$15,AD$15, $C59<$Z$16,AD$16)} -> 0.05 | AE59: {=_xlfn.IFS($C59<$Z$14,AE$14, $C59<$Z$15,AE$15, $C59<$Z$16,AE$16)} -> 0.03
B60: 0.84716646 | C60: =RAND() -> 0.53360359 | E60: {=_xlfn.IFS($C60<$D$14,E$14, $C60<$D$15,E$15, $C60<$D$16,E$16)} -> 0.1 | F60: {=_xlfn.IFS($C60<$D$14,F$14, $C60<$D$15,F$15, $C60<$D$16,F$16)} -> 0.05 | G60: {=_xlfn.IFS($C60<$D$14,G$14, $C60<$D$15,G$15, $C60<$D$16,G$16)} -> 0.05 | H60: {=_xlfn.IFS($C60<$D$14,H$14, $C60<$D$15,H$15, $C60<$D$16,H$16)} -> 0.1 | I60: {=_xlfn.IFS($C60<$D$14,I$14, $C60<$D$15,I$15, $C60<$D$16,I$16)} -> 0 | O60: {=_xlfn.IFS($C60<$D$14,O$14, $C60<$D$15,O$15, $C60<$D$16,O$16)} -> 0.05 | P60: {=_xlfn.IFS($C60<$D$14,P$14, $C60<$D$15,P$15, $C60<$D$16,P$16)} -> 0.04 | Q60: {=_xlfn.IFS($C60<$D$14,Q$14, $C60<$D$15,Q$15, $C60<$D$16,Q$16)} -> 0.08 | R60: {=_xlfn.IFS($C60<$D$14,R$14, $C60<$D$15,R$15, $C60<$D$16,R$16)} -> 0.06 | S60: {=_xlfn.IFS($C60<$D$14,S$14, $C60<$D$15,S$15, $C60<$D$16,S$16)} -> 0.04 | T60: {=_xlfn.IFS($C60<$D$14,T$14, $C60<$D$15,T$15, $C60<$D$16,T$16)} -> 0.05 | U60: {=_xlfn.IFS($C60<$D$14,U$14, $C60<$D$15,U$15, $C60<$D$16,U$16)} -> 0 | V60: {=_xlfn.IFS($C60<$D$14,V$14, $C60<$D$15,V$15, $C60<$D$16,V$16)} -> 10000 | AA60: {=_xlfn.IFS($C60<$Z$14,AA$14, $C60<$Z$15,AA$15, $C60<$Z$16,AA$16)} -> 0.14 | AB60: {=_xlfn.IFS($C60<$Z$14,AB$14, $C60<$Z$15,AB$15, $C60<$Z$16,AB$16)} -> 0.16 | AC60: {=_xlfn.IFS($C60<$Z$14,AC$14, $C60<$Z$15,AC$15, $C60<$Z$16,AC$16)} -> 0.2 | AD60: {=_xlfn.IFS($C60<$Z$14,AD$14, $C60<$Z$15,AD$15, $C60<$Z$16,AD$16)} -> 0.05 | AE60: {=_xlfn.IFS($C60<$Z$14,AE$14, $C60<$Z$15,AE$15, $C60<$Z$16,AE$16)} -> 0.03

Sheet Calc Engine
BE2: Deviations allowed | BF2: 0.1
BE3: % Of Goals Met | BF3: =COUNTIF(#REF!,"Goal Met")/COUNTA('Calc Engine'!$AL$8:$AL$17) -> #REF!
AM4: 1 - being least imp
E5: Goal | AP5: In Rs - Goal Value | BG5: Total Surplus | BH5: =SUM(Sum_Of_Wt_Adj_Surplus[Total]) -> -9481062.8
AP6: Source
AL7: Goal | AM7: Goal Importance | AN7: At Age | AP7: Large Cap | AQ7: Goal Met ? | AR7: Value At Age | AS7: Surplus | AT7: Wt_Adjusted_Surplus | AV7: Mid Cap | AW7: Goal Met ? | AX7: Value At Age | AY7: Surplus | AZ7: Wt_Adjusted_Surplus | BB7: Small Cap | BC7: Goal Met ? | BD7: Value At Age | BE7: Surplus | BF7: Wt_Adjusted_Surplus | BH7: Column1 | BI7: Total | BJ7: Goal Met ?
AL8: {=[1]!Goal_Input[Goal]} -> Own Health Fund | AM8: {=[1]!Goal_Input[Goal Importance]} -> 1 | AN8: {=[1]!Goal_Input[[At Age ]]} -> 32 | AP8: =[1]Details!M14 -> 660000 | AQ8: =IFERROR(IF(ISBLANK('Calc Engine'!$AL8),"No Goal",('Calc Engine'!$AP8*(1-$BF$2))<=_xlfn.XLOOKUP('Calc Engine'!$AN8,Age,End_Of_Year_Value_Large_Cap)),"-") -> FALSE | AR8: =IF('Calc Engine'!$AP8> 0,_xlfn.XLOOKUP(AN8,Age,End_Of_Year_Value_Large_Cap),0) -> 221864.68 | AS8: ='Calc Engine'!$AR8-'Calc Engine'!$AP8 -> -438135.32 | AT8: =PRODUCT('Calc Engine'!$AS8,'Calc Engine'!$AM8) -> -438135.32 | AV8: =[1]Details!N14 -> 0 | AW8: =IFERROR(IF(ISBLANK('Calc Engine'!$AL8),"No Goal",('Calc Engine'!$AV8*(1-$BF$2))<=_xlfn.XLOOKUP('Calc Engine'!$AN8,Age,End_Of_Year_Value_Mid_Cap)),"-") -> FALSE | AX8: =IF(Mid_Cap_Goal[[#This Row],[Mid Cap]]>0,_xlfn.XLOOKUP(AN8,Age,End_Of_Year_Value_Mid_Cap),0) -> 0 | AY8: ='Calc Engine'!$AX8-'Calc Engine'!$AV8 -> 0 | AZ8: =PRODUCT('Calc Engine'!$AY8,'Calc Engine'!$AM8) -> 0 | BB8: =[1]Details!O14 -> 0 | BC8: =IFERROR(IF(ISBLANK('Calc Engine'!$AL8),"No Goal",('Calc Engine'!$BB8 * (1 -$BF$2))<=_xlfn.XLOOKUP('Calc Engine'!$AN8,Age,End_Of_Year_Value_Small_Cap)),"-") -> TRUE | BD8: =IF(Small_Cap_Goal[[#This Row],[Small Cap]],_xlfn.XLOOKUP(AN8,Age,End_Of_Year_Value_Small_Cap),0) -> 0 | BE8: ='Calc Engine'!$BD8-'Calc Engine'!$BB8 -> 0 | BF8: =PRODUCT('Calc Engine'!$BE8,'Calc Engine'!$AM8) -> 0 | BH8: =AL8 -> Own Health Fund | BI8: =SUM(Small_Cap_Goal[[#This Row],[Wt_Adjusted_Surplus]],Mid_Cap_Goal[[#This Row],[Wt_Adjusted_Surplus]],Large_Cap_Goal[[#This Row],[Wt_Adjusted_Surplus]]) -> -438135.32 | BJ8: =Sum_Of_Wt_Adj_Surplus[[#This Row],[Total]]>0 -> FALSE
AL9: Marriage | AM9: 1 | AN9: 35 | AP9: =[1]Details!M15 -> 0 | AQ9: =IFERROR(IF(ISBLANK('Calc Engine'!$AL9),"No Goal",('Calc Engine'!$AP9*(1-$BF$2))<=_xlfn.XLOOKUP('Calc Engine'!$AN9,Age,End_Of_Year_Value_Large_Cap)),"-") -> FALSE | AR9: =IF('Calc Engine'!$AP9> 0,_xlfn.XLOOKUP(AN9,Age,End_Of_Year_Value_Large_Cap),0) -> 0 | AS9: ='Calc Engine'!$AR9-'Calc Engine'!$AP9 -> 0 | AT9: =PRODUCT('Calc Engine'!$AS9,'Calc Engine'!$AM9) -> 0 | AV9: =[1]Details!N15 -> 340000 | AW9: =IFERROR(IF(ISBLANK('Calc Engine'!$AL9),"No Goal",('Calc Engine'!$AV9*(1-$BF$2))<=_xlfn.XLOOKUP('Calc Engine'!$AN9,Age,End_Of_Year_Value_Mid_Cap)),"-") -> FALSE | AX9: =IF(Mid_Cap_Goal[[#This Row],[Mid Cap]]>0,_xlfn.XLOOKUP(AN9,Age,End_Of_Year_Value_Mid_Cap),0) -> -117195.6 | AY9: ='Calc Engine'!$AX9-'Calc Engine'!$AV9 -> -457195.6 | AZ9: =PRODUCT('Calc Engine'!$AY9,'Calc Engine'!$AM9) -> -457195.6 | BB9: =[1]Details!O15 -> 0 | BC9: =IFERROR(IF(ISBLANK('Calc Engine'!$AL9),"No Goal",('Calc Engine'!$BB9 * (1 -$BF$2))<=_xlfn.XLOOKUP('Calc Engine'!$AN9,Age,End_Of_Year_Value_Small_Cap)),"-") -> TRUE | BD9: =IF(Small_Cap_Goal[[#This Row],[Small Cap]],_xlfn.XLOOKUP(AN9,Age,End_Of_Year_Value_Small_Cap),0) -> 0 | BE9: ='Calc Engine'!$BD9-'Calc Engine'!$BB9 -> 0 | BF9: =PRODUCT('Calc Engine'!$BE9,'Calc Engine'!$AM9) -> 0 | BH9: =AL9 -> Marriage | BI9: =SUM(Small_Cap_Goal[[#This Row],[Wt_Adjusted_Surplus]],Mid_Cap_Goal[[#This Row],[Wt_Adjusted_Surplus]],Large_Cap_Goal[[#This Row],[Wt_Adjusted_Surplus]]) -> -457195.6 | BJ9: =Sum_Of_Wt_Adj_Surplus[[#This Row],[Total]]>0 -> FALSE
AL10: Children Education | AM10: 1 | AN10: 42 | AP10: =[1]Details!M16 -> 430000 | AQ10: =IFERROR(IF(ISBLANK('Calc Engine'!$AL10),"No Goal",('Calc Engine'!$AP10*(1-$BF$2))<=_xlfn.XLOOKUP('Calc Engine'!$AN10,Age,End_Of_Year_Value_Large_Cap)),"-") -> FALSE | AR10: =IF('Calc Engine'!$AP10> 0,_xlfn.XLOOKUP(AN10,Age,End_Of_Year_Value_Large_Cap),0) -> -1076850.7 | AS10: ='Calc Engine'!$AR10-'Calc Engine'!$AP10 -> -1506850.7 | AT10: =PRODUCT('Calc Engine'!$AS10,'Calc Engine'!$AM10) -> -1506850.7 | AV10: =[1]Details!N16 -> 0 | AW10: =IFERROR(IF(ISBLANK('Calc Engine'!$AL10),"No Goal",('Calc Engine'!$AV10*(1-$BF$2))<=_xlfn.XLOOKUP('Calc Engine'!$AN10,Age,End_Of_Year_Value_Mid_Cap)),"-") -> FALSE | AX10: =IF(Mid_Cap_Goal[[#This Row],[Mid Cap]]>0,_xlfn.XLOOKUP(AN10,Age,End_Of_Year_Value_Mid_Cap),0) -> 0 | AY10: ='Calc Engine'!$AX10-'Calc Engine'!$AV10 -> 0 | AZ10: =PRODUCT('Calc Engine'!$AY10,'Calc Engine'!$AM10) -> 0 | BB10: =[1]Details!O16 -> 0 | BC10: =IFERROR(IF(ISBLANK('Calc Engine'!$AL10),"No Goal",('Calc Engine'!$BB10 * (1 -$BF$2))<=_xlfn.XLOOKUP('Calc Engine'!$AN10,Age,End_Of_Year_Value_Small_Cap)),"-") -> TRUE | BD10: =IF(Small_Cap_Goal[[#This Row],[Small Cap]],_xlfn.XLOOKUP(AN10,Age,End_Of_Year_Value_Small_Cap),0) -> 0 | BE10: ='Calc Engine'!$BD10-'Calc Engine'!$BB10 -> 0 | BF10: =PRODUCT('Calc Engine'!$BE10,'Calc Engine'!$AM10) -> 0 | BH10: =AL10 -> Children Education | BI10: =SUM(Small_Cap_Goal[[#This Row],[Wt_Adjusted_Surplus]],Mid_Cap_Goal[[#This Row],[Wt_Adjusted_Surplus]],Large_Cap_Goal[[#This Row],[Wt_Adjusted_Surplus]]) -> -1506850.7 | BJ10: =Sum_Of_Wt_Adj_Surplus[[#This Row],[Total]]>0 -> FALSE
AL11: House | AM11: 1 | AN11: 52 | AP11: =[1]Details!M17 -> 6000000 | AQ11: =IFERROR(IF(ISBLANK('Calc Engine'!$AL11),"No Goal",('Calc Engine'!$AP11*(1-$BF$2))<=_xlfn.XLOOKUP('Calc Engine'!$AN11,Age,End_Of_Year_Value_Large_Cap)),"-") -> FALSE | AR11: =IF('Calc Engine'!$AP11> 0,_xlfn.XLOOKUP(AN11,Age,End_Of_Year_Value_Large_Cap),0) -> -4067740.7 | AS11: ='Calc Engine'!$AR11-'Calc Engine'!$AP11 -> -10067741 | AT11: =PRODUCT('Calc Engine'!$AS11,'Calc Engine'!$AM11) -> -10067741 | AV11: =[1]Details!N17 -> 0 | AW11: =IFERROR(IF(ISBLANK('Calc Engine'!$AL11),"No Goal",('Calc Engine'!$AV11*(1-$BF$2))<=_xlfn.XLOOKUP('Calc Engine'!$AN11,Age,End_Of_Year_Value_Mid_Cap)),"-") -> FALSE | AX11: =IF(Mid_Cap_Goal[[#This Row],[Mid Cap]]>0,_xlfn.XLOOKUP(AN11,Age,End_Of_Year_Value_Mid_Cap),0) -> 0 | AY11: ='Calc Engine'!$AX11-'Calc Engine'!$AV11 -> 0 | AZ11: =PRODUCT('Calc Engine'!$AY11,'Calc Engine'!$AM11) -> 0 | BB11: =[1]Details!O17 -> 0 | BC11: =IFERROR(IF(ISBLANK('Calc Engine'!$AL11),"No Goal",('Calc Engine'!$BB11 * (1 -$BF$2))<=_xlfn.XLOOKUP('Calc Engine'!$AN11,Age,End_Of_Year_Value_Small_Cap)),"-") -> TRUE | BD11: =IF(Small_Cap_Goal[[#This Row],[Small Cap]],_xlfn.XLOOKUP(AN11,Age,End_Of_Year_Value_Small_Cap),0) -> 0 | BE11: ='Calc Engine'!$BD11-'Calc Engine'!$BB11 -> 0 | BF11: =PRODUCT('Calc Engine'!$BE11,'Calc Engine'!$AM11) -> 0 | BH11: =AL11 -> House | BI11: =SUM(Small_Cap_Goal[[#This Row],[Wt_Adjusted_Surplus]],Mid_Cap_Goal[[#This Row],[Wt_Adjusted_Surplus]],Large_Cap_Goal[[#This Row],[Wt_Adjusted_Surplus]]) -> -10067741 | BJ11: =Sum_Of_Wt_Adj_Surplus[[#This Row],[Total]]>0 -> FALSE
AL12: Car | AM12: 1 | AN12: 28 | AP12: =[1]Details!M18 -> 0 | AQ12: =IFERROR(IF(ISBLANK('Calc Engine'!$AL12),"No Goal",('Calc Engine'!$AP12*(1-$BF$2))<=_xlfn.XLOOKUP('Calc Engine'!$AN12,Age,End_Of_Year_Value_Large_Cap)),"-") -> TRUE | AR12: =IF('Calc Engine'!$AP12> 0,_xlfn.XLOOKUP(AN12,Age,End_Of_Year_Value_Large_Cap),0) -> 0 | AS12: ='Calc Engine'!$AR12-'Calc Engine'!$AP12 -> 0 | AT12: =PRODUCT('Calc Engine'!$AS12,'Calc Engine'!$AM12) -> 0 | AV12: =[1]Details!N18 -> 209000 | AW12: =IFERROR(IF(ISBLANK('Calc Engine'!$AL12),"No Goal",('Calc Engine'!$AV12*(1-$BF$2))<=_xlfn.XLOOKUP('Calc Engine'!$AN12,Age,End_Of_Year_Value_Mid_Cap)),"-") -> FALSE | AX12: =IF(Mid_Cap_Goal[[#This Row],[Mid Cap]]>0,_xlfn.XLOOKUP(AN12,Age,End_Of_Year_Value_Mid_Cap),0) -> 107761.62 | AY12: ='Calc Engine'!$AX12-'Calc Engine'!$AV12 -> -101238.38 | AZ12: =PRODUCT('Calc Engine'!$AY12,'Calc Engine'!$AM12) -> -101238.38 | BB12: =[1]Details!O18 -> 0 | BC12: =IFERROR(IF(ISBLANK('Calc Engine'!$AL12),"No Goal",('Calc Engine'!$BB12 * (1 -$BF$2))<=_xlfn.XLOOKUP('Calc Engine'!$AN12,Age,End_Of_Year_Value_Small_Cap)),"-") -> TRUE | BD12: =IF(Small_Cap_Goal[[#This Row],[Small Cap]],_xlfn.XLOOKUP(AN12,Age,End_Of_Year_Value_Small_Cap),0) -> 0 | BE12: ='Calc Engine'!$BD12-'Calc Engine'!$BB12 -> 0 | BF12: =PRODUCT('Calc Engine'!$BE12,'Calc Engine'!$AM12) -> 0 | BH12: =AL12 -> Car | BI12: =SUM(Small_Cap_Goal[[#This Row],[Wt_Adjusted_Surplus]],Mid_Cap_Goal[[#This Row],[Wt_Adjusted_Surplus]],Large_Cap_Goal[[#This Row],[Wt_Adjusted_Surplus]]) -> -101238.38 | BJ12: =Sum_Of_Wt_Adj_Surplus[[#This Row],[Total]]>0 -> FALSE
AL13: Abroad Vacation | AM13: 1 | AN13: 38 | AP13: =[1]Details!M19 -> 0 | AQ13: =IFERROR(IF(ISBLANK('Calc Engine'!$AL13),"No Goal",('Calc Engine'!$AP13*(1-$BF$2))<=_xlfn.XLOOKUP('Calc Engine'!$AN13,Age,End_Of_Year_Value_Large_Cap)),"-") -> FALSE | AR13: =IF('Calc Engine'!$AP13> 0,_xlfn.XLOOKUP(AN13,Age,End_Of_Year_Value_Large_Cap),0) -> 0 | AS13: ='Calc Engine'!$AR13-'Calc Engine'!$AP13 -> 0 | AT13: =PRODUCT('Calc Engine'!$AS13,'Calc Engine'!$AM13) -> 0 | AV13: =[1]Details!N19 -> 0 | AW13: =IFERROR(IF(ISBLANK('Calc Engine'!$AL13),"No Goal",('Calc Engine'!$AV13*(1-$BF$2))<=_xlfn.XLOOKUP('Calc Engine'!$AN13,Age,End_Of_Year_Value_Mid_Cap)),"-") -> FALSE | AX13: =IF(Mid_Cap_Goal[[#This Row],[Mid Cap]]>0,_xlfn.XLOOKUP(AN13,Age,End_Of_Year_Value_Mid_Cap),0) -> 0 | AY13: ='Calc Engine'!$AX13-'Calc Engine'!$AV13 -> 0 | AZ13: =PRODUCT('Calc Engine'!$AY13,'Calc Engine'!$AM13) -> 0 | BB13: =[1]Details!O19 -> 5500000 | BC13: =IFERROR(IF(ISBLANK('Calc Engine'!$AL13),"No Goal",('Calc Engine'!$BB13 * (1 -$BF$2))<=_xlfn.XLOOKUP('Calc Engine'!$AN13,Age,End_Of_Year_Value_Small_Cap)),"-") -> TRUE | BD13: =IF(Small_Cap_Goal[[#This Row],[Small Cap]],_xlfn.XLOOKUP(AN13,Age,End_Of_Year_Value_Small_Cap),0) -> 8590097.9 | BE13: ='Calc Engine'!$BD13-'Calc Engine'!$BB13 -> 3090097.9 | BF13: =PRODUCT('Calc Engine'!$BE13,'Calc Engine'!$AM13) -> 3090097.9 | BH13: =AL13 -> Abroad Vacation | BI13: =SUM(Small_Cap_Goal[[#This Row],[Wt_Adjusted_Surplus]],Mid_Cap_Goal[[#This Row],[Wt_Adjusted_Surplus]],Large_Cap_Goal[[#This Row],[Wt_Adjusted_Surplus]]) -> 3090097.9 | BJ13: =Sum_Of_Wt_Adj_Surplus[[#This Row],[Total]]>0 -> TRUE
AL14: 0 | AM14: 1 | AN14: 0 | AP14: =[1]Details!M20 -> 0 | AQ14: =IFERROR(IF(ISBLANK('Calc Engine'!$AL14),"No Goal",('Calc Engine'!$AP14*(1-$BF$2))<=_xlfn.XLOOKUP('Calc Engine'!$AN14,Age,End_Of_Year_Value_Large_Cap)),"-") -> - | AR14: =IF('Calc Engine'!$AP14> 0,_xlfn.XLOOKUP(AN14,Age,End_Of_Year_Value_Large_Cap),0) -> 0 | AS14: ='Calc Engine'!$AR14-'Calc Engine'!$AP14 -> 0 | AT14: =PRODUCT('Calc Engine'!$AS14,'Calc Engine'!$AM14) -> 0 | AV14: =[1]Details!N20 -> 0 | AW14: =IFERROR(IF(ISBLANK('Calc Engine'!$AL14),"No Goal",('Calc Engine'!$AV14*(1-$BF$2))<=_xlfn.XLOOKUP('Calc Engine'!$AN14,Age,End_Of_Year_Value_Mid_Cap)),"-") -> - | AX14: =IF(Mid_Cap_Goal[[#This Row],[Mid Cap]]>0,_xlfn.XLOOKUP(AN14,Age,End_Of_Year_Value_Mid_Cap),0) -> 0 | AY14: ='Calc Engine'!$AX14-'Calc Engine'!$AV14 -> 0 | AZ14: =PRODUCT('Calc Engine'!$AY14,'Calc Engine'!$AM14) -> 0 | BB14: =[1]Details!O20 -> 0 | BC14: =IFERROR(IF(ISBLANK('Calc Engine'!$AL14),"No Goal",('Calc Engine'!$BB14 * (1 -$BF$2))<=_xlfn.XLOOKUP('Calc Engine'!$AN14,Age,End_Of_Year_Value_Small_Cap)),"-") -> - | BD14: =IF(Small_Cap_Goal[[#This Row],[Small Cap]],_xlfn.XLOOKUP(AN14,Age,End_Of_Year_Value_Small_Cap),0) -> 0 | BE14: ='Calc Engine'!$BD14-'Calc Engine'!$BB14 -> 0 | BF14: =PRODUCT('Calc Engine'!$BE14,'Calc Engine'!$AM14) -> 0 | BH14: =AL14 -> 0 | BI14: =SUM(Small_Cap_Goal[[#This Row],[Wt_Adjusted_Surplus]],Mid_Cap_Goal[[#This Row],[Wt_Adjusted_Surplus]],Large_Cap_Goal[[#This Row],[Wt_Adjusted_Surplus]]) -> 0 | BJ14: =Sum_Of_Wt_Adj_Surplus[[#This Row],[Total]]>0 -> FALSE
AL15: 0 | AM15: 1 | AN15: 0 | AP15: =[1]Details!M21 -> 0 | AQ15: =IFERROR(IF(ISBLANK('Calc Engine'!$AL15),"No Goal",('Calc Engine'!$AP15*(1-$BF$2))<=_xlfn.XLOOKUP('Calc Engine'!$AN15,Age,End_Of_Year_Value_Large_Cap)),"-") -> - | AR15: =IF('Calc Engine'!$AP15> 0,_xlfn.XLOOKUP(AN15,Age,End_Of_Year_Value_Large_Cap),0) -> 0 | AS15: ='Calc Engine'!$AR15-'Calc Engine'!$AP15 -> 0 | AT15: =PRODUCT('Calc Engine'!$AS15,'Calc Engine'!$AM15) -> 0 | AV15: =[1]Details!N21 -> 0 | AW15: =IFERROR(IF(ISBLANK('Calc Engine'!$AL15),"No Goal",('Calc Engine'!$AV15*(1-$BF$2))<=_xlfn.XLOOKUP('Calc Engine'!$AN15,Age,End_Of_Year_Value_Mid_Cap)),"-") -> - | AX15: =IF(Mid_Cap_Goal[[#This Row],[Mid Cap]]>0,_xlfn.XLOOKUP(AN15,Age,End_Of_Year_Value_Mid_Cap),0) -> 0 | AY15: ='Calc Engine'!$AX15-'Calc Engine'!$AV15 -> 0 | AZ15: =PRODUCT('Calc Engine'!$AY15,'Calc Engine'!$AM15) -> 0 | BB15: =[1]Details!O21 -> 0 | BC15: =IFERROR(IF(ISBLANK('Calc Engine'!$AL15),"No Goal",('Calc Engine'!$BB15 * (1 -$BF$2))<=_xlfn.XLOOKUP('Calc Engine'!$AN15,Age,End_Of_Year_Value_Small_Cap)),"-") -> - | BD15: =IF(Small_Cap_Goal[[#This Row],[Small Cap]],_xlfn.XLOOKUP(AN15,Age,End_Of_Year_Value_Small_Cap),0) -> 0 | BE15: ='Calc Engine'!$BD15-'Calc Engine'!$BB15 -> 0 | BF15: =PRODUCT('Calc Engine'!$BE15,'Calc Engine'!$AM15) -> 0 | BH15: =AL15 -> 0 | BI15: =SUM(Small_Cap_Goal[[#This Row],[Wt_Adjusted_Surplus]],Mid_Cap_Goal[[#This Row],[Wt_Adjusted_Surplus]],Large_Cap_Goal[[#This Row],[Wt_Adjusted_Surplus]]) -> 0 | BJ15: =Sum_Of_Wt_Adj_Surplus[[#This Row],[Total]]>0 -> FALSE
AL16: 0 | AM16: 1 | AN16: 0 | AP16: =[1]Details!M22 -> 0 | AQ16: =IFERROR(IF(ISBLANK('Calc Engine'!$AL16),"No Goal",('Calc Engine'!$AP16*(1-$BF$2))<=_xlfn.XLOOKUP('Calc Engine'!$AN16,Age,End_Of_Year_Value_Large_Cap)),"-") -> - | AR16: =IF('Calc Engine'!$AP16> 0,_xlfn.XLOOKUP(AN16,Age,End_Of_Year_Value_Large_Cap),0) -> 0 | AS16: ='Calc Engine'!$AR16-'Calc Engine'!$AP16 -> 0 | AT16: =PRODUCT('Calc Engine'!$AS16,'Calc Engine'!$AM16) -> 0 | AV16: =[1]Details!N22 -> 0 | AW16: =IFERROR(IF(ISBLANK('Calc Engine'!$AL16),"No Goal",('Calc Engine'!$AV16*(1-$BF$2))<=_xlfn.XLOOKUP('Calc Engine'!$AN16,Age,End_Of_Year_Value_Mid_Cap)),"-") -> - | AX16: =IF(Mid_Cap_Goal[[#This Row],[Mid Cap]]>0,_xlfn.XLOOKUP(AN16,Age,End_Of_Year_Value_Mid_Cap),0) -> 0 | AY16: ='Calc Engine'!$AX16-'Calc Engine'!$AV16 -> 0 | AZ16: =PRODUCT('Calc Engine'!$AY16,'Calc Engine'!$AM16) -> 0 | BB16: =[1]Details!O22 -> 0 | BC16: =IFERROR(IF(ISBLANK('Calc Engine'!$AL16),"No Goal",('Calc Engine'!$BB16 * (1 -$BF$2))<=_xlfn.XLOOKUP('Calc Engine'!$AN16,Age,End_Of_Year_Value_Small_Cap)),"-") -> - | BD16: =IF(Small_Cap_Goal[[#This Row],[Small Cap]],_xlfn.XLOOKUP(AN16,Age,End_Of_Year_Value_Small_Cap),0) -> 0 | BE16: ='Calc Engine'!$BD16-'Calc Engine'!$BB16 -> 0 | BF16: =PRODUCT('Calc Engine'!$BE16,'Calc Engine'!$AM16) -> 0 | BH16: =AL16 -> 0 | BI16: =SUM(Small_Cap_Goal[[#This Row],[Wt_Adjusted_Surplus]],Mid_Cap_Goal[[#This Row],[Wt_Adjusted_Surplus]],Large_Cap_Goal[[#This Row],[Wt_Adjusted_Surplus]]) -> 0 | BJ16: =Sum_Of_Wt_Adj_Surplus[[#This Row],[Total]]>0 -> FALSE
